<testsuite errors="0" failures="5" name="" skipped="0" tests="5" time="20.770">
<testcase classname="" name=".setUpClass (serial_scripts.k8s_auth.test_policy_combo.TestPolicyCombo)" time="0.000">
<failure type="testtools.testresult.real._StringException">Traceback (most recent call last):
testtools.testresult.real._StringException: Traceback (most recent call last):
  File "/contrail-test/serial_scripts/k8s_auth/test_policy_combo.py", line 22, in setUpClass
    super(TestPolicyCombo, cls).setUpClass()
  File "/contrail-test/serial_scripts/k8s_auth/base.py", line 14, in setUpClass
    dstdir='/var/tmp/templates')
  File "/contrail-test/common/contrail_test_init.py", line 1610, in copy_file_to_server
    host['username'] = self.host_data[ip]['username']
KeyError: '192.168.7.18'

</failure>
</testcase>
<testcase classname="" name=".setUpClass (serial_scripts.k8s_auth.test_resource.TestK8sResource)" time="0.000">
<failure type="testtools.testresult.real._StringException">Traceback (most recent call last):
testtools.testresult.real._StringException: Traceback (most recent call last):
  File "/contrail-test/serial_scripts/k8s_auth/test_resource.py", line 23, in setUpClass
    super(TestK8sResource, cls).setUpClass()
  File "/contrail-test/serial_scripts/k8s_auth/base.py", line 14, in setUpClass
    dstdir='/var/tmp/templates')
  File "/contrail-test/common/contrail_test_init.py", line 1610, in copy_file_to_server
    host['username'] = self.host_data[ip]['username']
KeyError: '192.168.7.18'

</failure>
</testcase>
<testcase classname="" name=".setUpClass (serial_scripts.k8s_auth.test_resource.TestK8sResourceCustom)" time="0.000">
<failure type="testtools.testresult.real._StringException">Traceback (most recent call last):
testtools.testresult.real._StringException: Traceback (most recent call last):
  File "/contrail-test/serial_scripts/k8s_auth/test_resource.py", line 74, in setUpClass
    super(TestK8sResourceCustom, cls).setUpClass()
  File "/contrail-test/serial_scripts/k8s_auth/base.py", line 14, in setUpClass
    dstdir='/var/tmp/templates')
  File "/contrail-test/common/contrail_test_init.py", line 1610, in copy_file_to_server
    host['username'] = self.host_data[ip]['username']
KeyError: '192.168.7.18'

</failure>
</testcase>
<testcase classname="" name=".setUpClass (serial_scripts.k8s_auth.test_restart.TestRestart)" time="0.000">
<failure type="testtools.testresult.real._StringException">Traceback (most recent call last):
testtools.testresult.real._StringException: Traceback (most recent call last):
  File "/contrail-test/serial_scripts/k8s_auth/test_restart.py", line 22, in setUpClass
    super(TestRestart, cls).setUpClass()
  File "/contrail-test/serial_scripts/k8s_auth/base.py", line 14, in setUpClass
    dstdir='/var/tmp/templates')
  File "/contrail-test/common/contrail_test_init.py", line 1610, in copy_file_to_server
    host['username'] = self.host_data[ip]['username']
KeyError: '192.168.7.18'

</failure>
</testcase>
<testcase classname="" name=".setUpClass (serial_scripts.k8s_auth.test_restart.TestRestartWithPodResource)" time="0.000">
<failure type="testtools.testresult.real._StringException">Traceback (most recent call last):
testtools.testresult.real._StringException: Traceback (most recent call last):
  File "/contrail-test/serial_scripts/k8s_auth/test_restart.py", line 130, in setUpClass
    super(TestRestartWithPodResource, cls).setUpClass()
  File "/contrail-test/serial_scripts/k8s_auth/base.py", line 14, in setUpClass
    dstdir='/var/tmp/templates')
  File "/contrail-test/common/contrail_test_init.py", line 1610, in copy_file_to_server
    host['username'] = self.host_data[ip]['username']
KeyError: '192.168.7.18'

</failure>
</testcase>
</testsuite>