2021-02-22 05:05:54,595 - INFO - Reading existing Domain with UUID f27c063f-c6c4-434f-a616-97e72e0043e5
2021-02-22 05:05:54,627 - INFO - Using existing domain ['admin_domain'](f27c063f-c6c4-434f-a616-97e72e0043e5)
2021-02-22 05:05:54,975 - INFO - Project ctest-TestBasicVMVNx-82901118 not found, creating it
2021-02-22 05:05:55,583 - INFO - Created Project:ctest-TestBasicVMVNx-82901118, ID : 4d0e2cb6-0f42-413b-b1f7-a63e7971f1eb 
2021-02-22 05:05:59,585 - INFO - ================================================================================
2021-02-22 05:05:59,585 - INFO - STARTING TEST    : test_vm_file_trf_scp_tests
2021-02-22 05:05:59,586 - INFO - TEST DESCRIPTION : 
        Description: Test to validate File Transfer using scp between VMs. Files of different sizes.
        Test steps:
                1. Creating vm's - vm1 and vm2 and a Vn - vn222
                2. Transfer file from vm1 to vm2 with diferrent file sizes using scp
                3. file sizes - 64,1202,2210,10000
                4. verify files present in vm2 match with the size of the file sent.
        Pass criteria: File in vm2 should match with the transferred file size from vm1

        Maintainer : ganeshahv@juniper.net
        
2021-02-22 05:06:00,960 - DEBUG - Nothing to compare xmpp stats {'192.168.7.19': {'192.168.27.20': '0', '192.168.27.34': '0'}, '192.168.7.9': {'192.168.27.20': '0', '192.168.27.34': '0'}} with
2021-02-22 05:06:00,960 - INFO - Initial checks done. Running the testcase now
2021-02-22 05:06:00,960 - INFO - 
2021-02-22 05:06:02,174 - DEBUG - Response for create_network : {'network': {'status': 'ACTIVE', 'router:external': False, 'subnets': [], 'fq_name': ['admin_domain', 'ctest-TestBasicVMVNx-82901118', 'ctest-vn-97115262'], 'name': 'ctest-vn-97115262', 'admin_state_up': True, 'tenant_id': '4d0e2cb60f42413bb1f7a63e7971f1eb', 'created_at': None, 'updated_at': None, 'shared': False, 'port_security_enabled': True, 'project_id': '4d0e2cb60f42413bb1f7a63e7971f1eb', 'id': '9c203277-9347-4972-8772-75dfb7839ce3', 'description': ''}}
2021-02-22 05:06:02,478 - DEBUG - Response for create_subnet : {'subnet': {'name': '', 'enable_dhcp': True, 'network_id': '9c203277-9347-4972-8772-75dfb7839ce3', 'tenant_id': '4d0e2cb60f42413bb1f7a63e7971f1eb', 'created_at': '2021-02-22T05:06:01.846835', 'dns_nameservers': [], 'updated_at': '2021-02-22T05:06:01.846835', 'ipv6_ra_mode': None, 'allocation_pools': [{'start': '83.94.112.130', 'end': '83.94.112.190'}], 'gateway_ip': '83.94.112.129', 'dns_server_address': '83.94.112.130', 'ipv6_address_mode': None, 'ip_version': 4, 'host_routes': [], 'cidr': '83.94.112.128/26', 'id': 'cfd7daa1-8079-4d72-9d8f-443b93dd5357'}}
2021-02-22 05:06:02,529 - INFO - Created VN ctest-vn-97115262
2021-02-22 05:06:02,562 - DEBUG - VN ctest-vn-97115262 UUID is 9c203277-9347-4972-8772-75dfb7839ce3
2021-02-22 05:06:03,022 - DEBUG - Services list from nova: [<Service: 1>, <Service: 3>, <Service: 4>, <Service: 16>]
2021-02-22 05:07:33,861 - INFO - Deleting VN ctest-vn-97115262 
2021-02-22 05:07:34,117 - DEBUG - Response for deleting network ()
2021-02-22 05:07:35,413 - ERROR - ConnectFailure
Python 3.6.8: /usr/bin/python3
Mon Feb 22 05:07:33 2021

A problem occurred in a Python script.  Here is the sequence of
function calls leading up to the error, in the order they occurred.

 /contrail-test/tcutils/wrappers.py in wrapper(self=<scripts.vm_regression.test_vm.TestBasicVMVNx.te...ty,vcenter_compute,vrouter_gw] id=0x7fa56c048b38>, *args=(), **kwargs={})
   80             log.info('Initial checks done. Running the testcase now')
   81             log.info('')
   82             result = function(self, *args, **kwargs)
   83             if self.inputs.upgrade:
   84                 pid = os.getpid()
result = None
function = <function TestBasicVMVNx.test_vm_file_trf_scp_tests>
self = <scripts.vm_regression.test_vm.TestBasicVMVNx.te...ty,vcenter_compute,vrouter_gw] id=0x7fa56c048b38>
args = ()
kwargs = {}

 /contrail-test/scripts/vm_regression/test_vm.py in test_vm_file_trf_scp_tests(self=<scripts.vm_regression.test_vm.TestBasicVMVNx.te...ty,vcenter_compute,vrouter_gw] id=0x7fa56c048b38>)
 2798         vm1_fixture = self.create_vm(vn_fixture=vn_fixture,
 2799             image_name='ubuntu',
 2800             orch=self.orchestrator)
 2801         vm2_fixture = self.create_vm(vn_fixture=vn_fixture,
 2802             image_name='ubuntu')
orch undefined
self = <scripts.vm_regression.test_vm.TestBasicVMVNx.te...ty,vcenter_compute,vrouter_gw] id=0x7fa56c048b38>
self.orchestrator = <openstack.OpenstackOrchestrator object>

 /contrail-test/common/base.py in create_vm(self=<scripts.vm_regression.test_vm.TestBasicVMVNx.te...ty,vcenter_compute,vrouter_gw] id=0x7fa56c048b38>, vn_fixture=<vn_test.VNFixture object>, vm_name=None, image_name='ubuntu', port_ids=None, **kwargs={'orch': <openstack.OpenstackOrchestrator object>})
  290                         image_name=image_name,
  291                         port_ids=port_ids,
  292                         **kwargs)
  293         if cleanup:
  294             self.addCleanup(vm_fixture.cleanUp)
kwargs = {'orch': <openstack.OpenstackOrchestrator object>}

 /contrail-test/common/base.py in create_only_vm(cls=<class 'scripts.vm_regression.test_vm.TestBasicVMVNx'>, vn_fixture=<vn_test.VNFixture object>, vm_name=None, image_name='ubuntu', **kwargs={'orch': <openstack.OpenstackOrchestrator object>, 'port_ids': None})
  263                     image_name=image_name,
  264                     **kwargs)
  265         vm_obj.setUp()
  266         return vm_obj
  267     # end create_only_vm
vm_obj = <VMFixture: ctest-TestBasicVMVNx-82901118-54551980>
vm_obj.setUp = <bound method VMFixture.setUp of <VMFixture: ctest-TestBasicVMVNx-82901118-54551980>>

 /contrail-test/fixtures/vm_test.py in setUp(self=<VMFixture: ctest-TestBasicVMVNx-82901118-54551980>)
  207     def setUp(self):
  208         super(VMFixture, self).setUp()
  209         self.create()
  210 
  211     def create(self):
self = <VMFixture: ctest-TestBasicVMVNx-82901118-54551980>
self.create = <bound method VMFixture.create of <VMFixture: ctest-TestBasicVMVNx-82901118-54551980>>

 /contrail-test/fixtures/vm_test.py in create(self=<VMFixture: ctest-TestBasicVMVNx-82901118-54551980>)
  260                     userdata=self.userdata,
  261                     port_ids=self.port_ids,
  262                     fixed_ips=self.fixed_ips)
  263                 self.created = True
  264                 self.vm_obj = objs[0]
fixed_ips undefined
self = <VMFixture: ctest-TestBasicVMVNx-82901118-54551980>
self.fixed_ips = []

 /contrail-test/fixtures/openstack.py in create_vm(self=<openstack.OpenstackOrchestrator object>, vm_name='ctest-TestBasicVMVNx-82901118-54551980', image_name='ubuntu', vn_objs=[{'network': {'status': 'ACTIVE', 'router:externa...9347-4972-8772-75dfb7839ce3', 'description': ''}}], **kwargs={'count': 1, 'fixed_ips': [], 'flavor': 'contrail_flavor_tiny', 'node_name': None, 'port_ids': None, 'project_uuid': '4d0e2cb6-0f42-413b-b1f7-a63e7971f1eb', 'sg_ids': [], 'userdata': None, 'zone': None})
  138            except Exception as e:
  139                vn_ids.append(vn.uuid) #For the case of VcenterVN obnect in vrouter gw case
  140        return self.nova_h.create_vm(vm_name=vm_name, image_name=image_name, vn_ids=vn_ids, **kwargs)
  141 
  142    def delete_vm(self, vm_obj, **kwargs):
self = <openstack.OpenstackOrchestrator object>
self.nova_h = <nova_test.NovaHelper object>
self.nova_h.create_vm = <bound method NovaHelper.create_vm of <nova_test.NovaHelper object>>
vm_name = 'ctest-TestBasicVMVNx-82901118-54551980'
image_name = 'ubuntu'
vn_ids = ['9c203277-9347-4972-8772-75dfb7839ce3']
kwargs = {'count': 1, 'fixed_ips': [], 'flavor': 'contrail_flavor_tiny', 'node_name': None, 'port_ids': None, 'project_uuid': '4d0e2cb6-0f42-413b-b1f7-a63e7971f1eb', 'sg_ids': [], 'userdata': None, 'zone': None}

 /contrail-test/fixtures/nova_test.py in create_vm(self=<nova_test.NovaHelper object>, project_uuid='4d0e2cb6-0f42-413b-b1f7-a63e7971f1eb', image_name='ubuntu', vm_name='ctest-TestBasicVMVNx-82901118-54551980', vn_ids=['9c203277-9347-4972-8772-75dfb7839ce3'], node_name='nodec9', sg_ids=[], count=1, userdata=None, flavor=<Flavor: contrail_flavor_tiny>, port_ids=None, fixed_ips=[], zone='nova:nodec9')
  615                                 config_drive=config_drive,
  616                                 key_name=self.key, availability_zone=zone,
  617                                 min_count=count, max_count=count, userdata=userdata)
  618         vm_objs = self.get_vm_list(name_pattern=vm_name,
  619                                    project_id=project_uuid)
min_count undefined
count = 1
max_count undefined
userdata = None

 /usr/local/lib/python3.6/site-packages/novaclient/v2/servers.py in create(self=<novaclient.v2.servers.ServerManager object>, name='ctest-TestBasicVMVNx-82901118-54551980', image=<RequestIdProxy at 0x7fa56f36c948 for image>, flavor=<Flavor: contrail_flavor_tiny>, meta=None, files=None, reservation_id=False, min_count=1, max_count=1, security_groups=[], userdata=None, key_name='ctest_ctest-TestBasicVMVNx-82901118ctest-TestBasicVMVNx-82901118key1', availability_zone='nova:nodec9', block_device_mapping=None, block_device_mapping_v2=None, nics=[{'net-id': '9c203277-9347-4972-8772-75dfb7839ce3'}], scheduler_hints=None, config_drive=False, disk_config=None, admin_pass=None, access_ip_v4=None, access_ip_v6=None, trusted_image_certificates=None, host=None, hypervisor_hostname=None, **kwargs={})
 1479 
 1480         response_key = "server" if not reservation_id else "reservation_id"
 1481         return self._boot(response_key, *boot_args, **boot_kwargs)
 1482 
 1483     @api_versions.wraps("2.0", "2.18")
self = <novaclient.v2.servers.ServerManager object>
self._boot = <bound method ServerManager._boot of <novaclient.v2.servers.ServerManager object>>
response_key = 'server'
boot_args = ['ctest-TestBasicVMVNx-82901118-54551980', <RequestIdProxy at 0x7fa56f36c948 for image>, <Flavor: contrail_flavor_tiny>]
boot_kwargs = {'access_ip_v4': None, 'access_ip_v6': None, 'admin_pass': None, 'availability_zone': 'nova:nodec9', 'config_drive': False, 'disk_config': None, 'files': None, 'host': None, 'hypervisor_hostname': None, 'key_name': 'ctest_ctest-TestBasicVMVNx-82901118ctest-TestBasicVMVNx-82901118key1', ...}

 /usr/local/lib/python3.6/site-packages/novaclient/v2/servers.py in _boot(self=<novaclient.v2.servers.ServerManager object>, response_key='server', name='ctest-TestBasicVMVNx-82901118-54551980', image=<RequestIdProxy at 0x7fa56f36c948 for image>, flavor=<Flavor: contrail_flavor_tiny>, meta=None, files=None, userdata=None, reservation_id=False, return_raw=False, min_count=1, max_count=1, security_groups=[], key_name='ctest_ctest-TestBasicVMVNx-82901118ctest-TestBasicVMVNx-82901118key1', availability_zone='nova:nodec9', block_device_mapping=None, block_device_mapping_v2=None, nics=[{'net-id': '9c203277-9347-4972-8772-75dfb7839ce3'}], scheduler_hints=None, config_drive=False, admin_pass=None, disk_config=None, access_ip_v4=None, access_ip_v6=None, description=None, tags=None, trusted_image_certificates=None, host=None, hypervisor_hostname=None, **kwargs={})
  844 
  845         return self._create('/servers', body, response_key,
  846                             return_raw=return_raw, **kwargs)
  847 
  848     def get(self, server):
return_raw = False
kwargs = {}

 /usr/local/lib/python3.6/site-packages/novaclient/base.py in _create(self=<novaclient.v2.servers.ServerManager object>, url='/servers', body={'server': {'availability_zone': 'nova:nodec9', 'flavorRef': 'a91f54af-e009-4d84-96b6-789c2a4050f1', 'imageRef': '78f9a98e-a938-43c2-ad3e-578c4cde1f16', 'key_name': 'ctest_ctest-TestBasicVMVNx-82901118ctest-TestBasicVMVNx-82901118key1', 'max_count': 1, 'min_count': 1, 'name': 'ctest-TestBasicVMVNx-82901118-54551980', 'networks': [{'uuid': '9c203277-9347-4972-8772-75dfb7839ce3'}]}}, response_key='server', return_raw=False, obj_class=None, **kwargs={})
  362                 obj_class=None, **kwargs):
  363         self.run_hooks('modify_body_for_create', body, **kwargs)
  364         resp, body = self.api.client.post(url, body=body)
  365         if return_raw:
  366             return self.convert_into_with_meta(body[response_key], resp)
resp undefined
body = {'server': {'availability_zone': 'nova:nodec9', 'flavorRef': 'a91f54af-e009-4d84-96b6-789c2a4050f1', 'imageRef': '78f9a98e-a938-43c2-ad3e-578c4cde1f16', 'key_name': 'ctest_ctest-TestBasicVMVNx-82901118ctest-TestBasicVMVNx-82901118key1', 'max_count': 1, 'min_count': 1, 'name': 'ctest-TestBasicVMVNx-82901118-54551980', 'networks': [{'uuid': '9c203277-9347-4972-8772-75dfb7839ce3'}]}}
self = <novaclient.v2.servers.ServerManager object>
self.api = <novaclient.v2.client.Client object>
self.api.client = <novaclient.client.SessionClient object>
self.api.client.post = <bound method Adapter.post of <novaclient.client.SessionClient object>>
url = '/servers'

 /usr/local/lib/python3.6/site-packages/keystoneauth1/adapter.py in post(self=<novaclient.client.SessionClient object>, url='/servers', **kwargs={'body': {'server': {'availability_zone': 'nova:nodec9', 'flavorRef': 'a91f54af-e009-4d84-96b6-789c2a4050f1', 'imageRef': '78f9a98e-a938-43c2-ad3e-578c4cde1f16', 'key_name': 'ctest_ctest-TestBasicVMVNx-82901118ctest-TestBasicVMVNx-82901118key1', 'max_count': 1, 'min_count': 1, 'name': 'ctest-TestBasicVMVNx-82901118-54551980', 'networks': [{'uuid': '9c203277-9347-4972-8772-75dfb7839ce3'}]}}})
  390 
  391     def post(self, url, **kwargs):
  392         return self.request(url, 'POST', **kwargs)
  393 
  394     def put(self, url, **kwargs):
self = <novaclient.client.SessionClient object>
self.request = <bound method SessionClient.request of <novaclient.client.SessionClient object>>
url = '/servers'
kwargs = {'body': {'server': {'availability_zone': 'nova:nodec9', 'flavorRef': 'a91f54af-e009-4d84-96b6-789c2a4050f1', 'imageRef': '78f9a98e-a938-43c2-ad3e-578c4cde1f16', 'key_name': 'ctest_ctest-TestBasicVMVNx-82901118ctest-TestBasicVMVNx-82901118key1', 'max_count': 1, 'min_count': 1, 'name': 'ctest-TestBasicVMVNx-82901118-54551980', 'networks': [{'uuid': '9c203277-9347-4972-8772-75dfb7839ce3'}]}}}

 /usr/local/lib/python3.6/site-packages/novaclient/client.py in request(self=<novaclient.client.SessionClient object>, url='/servers', method='POST', **kwargs={'body': {'server': {'availability_zone': 'nova:nodec9', 'flavorRef': 'a91f54af-e009-4d84-96b6-789c2a4050f1', 'imageRef': '78f9a98e-a938-43c2-ad3e-578c4cde1f16', 'key_name': 'ctest_ctest-TestBasicVMVNx-82901118ctest-TestBasicVMVNx-82901118key1', 'max_count': 1, 'min_count': 1, 'name': 'ctest-TestBasicVMVNx-82901118-54551980', 'networks': [{'uuid': '9c203277-9347-4972-8772-75dfb7839ce3'}]}}, 'headers': {'Accept': 'application/json', 'Content-Type': 'application/json', 'User-Agent': 'python-novaclient', 'X-Auth-Token': '8e9e21c0b1b346819012c08655c8db61'}})
   70                                                             method,
   71                                                             raise_exc=False,
   72                                                             **kwargs)
   73 
   74         # TODO(andreykurilin): uncomment this line, when we will be able to
kwargs = {'body': {'server': {'availability_zone': 'nova:nodec9', 'flavorRef': 'a91f54af-e009-4d84-96b6-789c2a4050f1', 'imageRef': '78f9a98e-a938-43c2-ad3e-578c4cde1f16', 'key_name': 'ctest_ctest-TestBasicVMVNx-82901118ctest-TestBasicVMVNx-82901118key1', 'max_count': 1, 'min_count': 1, 'name': 'ctest-TestBasicVMVNx-82901118-54551980', 'networks': [{'uuid': '9c203277-9347-4972-8772-75dfb7839ce3'}]}}, 'headers': {'Accept': 'application/json', 'Content-Type': 'application/json', 'User-Agent': 'python-novaclient', 'X-Auth-Token': '8e9e21c0b1b346819012c08655c8db61'}}

 /usr/local/lib/python3.6/site-packages/keystoneauth1/adapter.py in request(self=<novaclient.client.SessionClient object>, *args=('/servers', 'POST'), **kwargs={'headers': {'Accept': 'application/json', 'Content-Type': 'application/json', 'User-Agent': 'python-novaclient', 'X-Auth-Token': '8e9e21c0b1b346819012c08655c8db61'}, 'json': {'server': {'availability_zone': 'nova:nodec9', 'flavorRef': 'a91f54af-e009-4d84-96b6-789c2a4050f1', 'imageRef': '78f9a98e-a938-43c2-ad3e-578c4cde1f16', 'key_name': 'ctest_ctest-TestBasicVMVNx-82901118ctest-TestBasicVMVNx-82901118key1', 'max_count': 1, 'min_count': 1, 'name': 'ctest-TestBasicVMVNx-82901118-54551980', 'networks': [{'uuid': '9c203277-9347-4972-8772-75dfb7839ce3'}]}}, 'raise_exc': False})
  543             pass
  544 
  545         resp = super(LegacyJsonAdapter, self).request(*args, **kwargs)
  546 
  547         try:
resp undefined
builtinsuper = <class 'super'>
global LegacyJsonAdapter = <class 'keystoneauth1.adapter.LegacyJsonAdapter'>
self = <novaclient.client.SessionClient object>
).request = <bound method SessionClient.request of <novaclient.client.SessionClient object>>
args = ('/servers', 'POST')
kwargs = {'headers': {'Accept': 'application/json', 'Content-Type': 'application/json', 'User-Agent': 'python-novaclient', 'X-Auth-Token': '8e9e21c0b1b346819012c08655c8db61'}, 'json': {'server': {'availability_zone': 'nova:nodec9', 'flavorRef': 'a91f54af-e009-4d84-96b6-789c2a4050f1', 'imageRef': '78f9a98e-a938-43c2-ad3e-578c4cde1f16', 'key_name': 'ctest_ctest-TestBasicVMVNx-82901118ctest-TestBasicVMVNx-82901118key1', 'max_count': 1, 'min_count': 1, 'name': 'ctest-TestBasicVMVNx-82901118-54551980', 'networks': [{'uuid': '9c203277-9347-4972-8772-75dfb7839ce3'}]}}, 'raise_exc': False}

 /usr/local/lib/python3.6/site-packages/keystoneauth1/adapter.py in request(self=<novaclient.client.SessionClient object>, url='/servers', method='POST', **kwargs={'client_name': 'python-novaclient', 'client_version': '16.0.0', 'endpoint_filter': {'interface': 'publicURL', 'region_name': 'RegionOne', 'service_type': 'compute'}, 'headers': {'Accept': 'application/json', 'Content-Type': 'application/json', 'User-Agent': 'python-novaclient', 'X-Auth-Token': '8e9e21c0b1b346819012c08655c8db61'}, 'json': {'server': {'availability_zone': 'nova:nodec9', 'flavorRef': 'a91f54af-e009-4d84-96b6-789c2a4050f1', 'imageRef': '78f9a98e-a938-43c2-ad3e-578c4cde1f16', 'key_name': 'ctest_ctest-TestBasicVMVNx-82901118ctest-TestBasicVMVNx-82901118key1', 'max_count': 1, 'min_count': 1, 'name': 'ctest-TestBasicVMVNx-82901118-54551980', 'networks': [{'uuid': '9c203277-9347-4972-8772-75dfb7839ce3'}]}}, 'raise_exc': False, 'rate_semaphore': <keystoneauth1._fair_semaphore.FairSemaphore object>, 'user_agent': 'python-novaclient'})
  246             kwargs.setdefault('raise_exc', self.raise_exc)
  247 
  248         return self.session.request(url, method, **kwargs)
  249 
  250     def get_token(self, auth=None):
self = <novaclient.client.SessionClient object>
self.session = <keystoneauth1.session.Session object>
self.session.request = <bound method Session.request of <keystoneauth1.session.Session object>>
url = '/servers'
method = 'POST'
kwargs = {'client_name': 'python-novaclient', 'client_version': '16.0.0', 'endpoint_filter': {'interface': 'publicURL', 'region_name': 'RegionOne', 'service_type': 'compute'}, 'headers': {'Accept': 'application/json', 'Content-Type': 'application/json', 'User-Agent': 'python-novaclient', 'X-Auth-Token': '8e9e21c0b1b346819012c08655c8db61'}, 'json': {'server': {'availability_zone': 'nova:nodec9', 'flavorRef': 'a91f54af-e009-4d84-96b6-789c2a4050f1', 'imageRef': '78f9a98e-a938-43c2-ad3e-578c4cde1f16', 'key_name': 'ctest_ctest-TestBasicVMVNx-82901118ctest-TestBasicVMVNx-82901118key1', 'max_count': 1, 'min_count': 1, 'name': 'ctest-TestBasicVMVNx-82901118-54551980', 'networks': [{'uuid': '9c203277-9347-4972-8772-75dfb7839ce3'}]}}, 'raise_exc': False, 'rate_semaphore': <keystoneauth1._fair_semaphore.FairSemaphore object>, 'user_agent': 'python-novaclient'}

 /usr/local/lib/python3.6/site-packages/keystoneauth1/session.py in request(self=<keystoneauth1.session.Session object>, url='http://192.168.7.12:8774/v2.1/servers', method='POST', json={'server': {'availability_zone': 'nova:nodec9', 'flavorRef': 'a91f54af-e009-4d84-96b6-789c2a4050f1', 'imageRef': '78f9a98e-a938-43c2-ad3e-578c4cde1f16', 'key_name': 'ctest_ctest-TestBasicVMVNx-82901118ctest-TestBasicVMVNx-82901118key1', 'max_count': 1, 'min_count': 1, 'name': 'ctest-TestBasicVMVNx-82901118-54551980', 'networks': [{'uuid': '9c203277-9347-4972-8772-75dfb7839ce3'}]}}, original_ip=None, user_agent='python-novaclient', redirect=30, authenticated=True, endpoint_filter={'interface': 'publicURL', 'region_name': 'RegionOne', 'service_type': 'compute'}, auth=None, requests_auth=None, raise_exc=False, allow_reauth=True, log=True, endpoint_override=None, connect_retries=0, logger=<Logger keystoneauth.session (WARNING)>, allow=None, client_name='python-novaclient', client_version='16.0.0', microversion=None, microversion_service_type=None, status_code_retries=0, retriable_status_codes=[503], rate_semaphore=<keystoneauth1._fair_semaphore.FairSemaphore object>, global_request_id=None, connect_retry_delay=None, status_code_retry_delay=None, **kwargs={'allow_redirects': False, 'cert': (None, None), 'data': '{"server": {"name": "ctest-TestBasicVMVNx-829011...uuid": "9c203277-9347-4972-8772-75dfb7839ce3"}]}}', 'headers': {'Accept': 'application/json', 'Content-Type': 'application/json', 'User-Agent': 'python-novaclient', 'X-Auth-Token': '8e9e21c0b1b346819012c08655c8db61'}, 'verify': False})
  911                 kwargs.update(connection_params)
  912 
  913         resp = send(**kwargs)
  914 
  915         # log callee and caller request-id for each api call
resp undefined
send = functools.partial(<bound method Session._send_re...auth1.session._Retries object at 0x7fa56a62dac8>)
kwargs = {'allow_redirects': False, 'cert': (None, None), 'data': '{"server": {"name": "ctest-TestBasicVMVNx-829011...uuid": "9c203277-9347-4972-8772-75dfb7839ce3"}]}}', 'headers': {'Accept': 'application/json', 'Content-Type': 'application/json', 'User-Agent': 'python-novaclient', 'X-Auth-Token': '8e9e21c0b1b346819012c08655c8db61'}, 'verify': False}

 /usr/local/lib/python3.6/site-packages/keystoneauth1/session.py in _send_request(self=<keystoneauth1.session.Session object>, url='http://192.168.7.12:8774/v2.1/servers', method='POST', redirect=30, log=True, logger=<Logger keystoneauth.session (WARNING)>, split_loggers=None, connect_retries=0, status_code_retries=0, retriable_status_codes=[503], rate_semaphore=<keystoneauth1._fair_semaphore.FairSemaphore object>, connect_retry_delays=<keystoneauth1.session._Retries object>, status_code_retry_delays=<keystoneauth1.session._Retries object>, **kwargs={'allow_redirects': False, 'cert': (None, None), 'data': '{"server": {"name": "ctest-TestBasicVMVNx-829011...uuid": "9c203277-9347-4972-8772-75dfb7839ce3"}]}}', 'headers': {'Accept': 'application/json', 'Content-Type': 'application/json', 'User-Agent': 'python-novaclient', 'X-Auth-Token': '8e9e21c0b1b346819012c08655c8db61'}, 'verify': False})
 1018                 # and firewall blocking.
 1019                 msg = 'Unable to establish connection to %s: %s' % (url, e)
 1020                 raise exceptions.ConnectFailure(msg)
 1021             except requests.exceptions.RequestException as e:
 1022                 msg = 'Unexpected exception for %(url)s: %(error)s' % {
global exceptions = <module 'keystoneauth1.exceptions' from '/usr/lo...e-packages/keystoneauth1/exceptions/__init__.py'>
exceptions.ConnectFailure = <class 'keystoneauth1.exceptions.connection.ConnectFailure'>
msg = "Unable to establish connection to http://192.168...Remote end closed connection without response',))"
ConnectFailure: Unable to establish connection to http://192.168.7.12:8774/v2.1/servers: ('Connection aborted.', RemoteDisconnected('Remote end closed connection without response',))
    __cause__ = None
    __class__ = <class 'keystoneauth1.exceptions.connection.ConnectFailure'>
    __context__ = ConnectionError(ProtocolError('Connection aborte...mote end closed connection without response',)),)
    __delattr__ = <method-wrapper '__delattr__' of ConnectFailure object>
    __dict__ = {'message': "Unable to establish connection to http://192.168...Remote end closed connection without response',))"}
    __dir__ = <built-in method __dir__ of ConnectFailure object>
    __doc__ = None
    __eq__ = <method-wrapper '__eq__' of ConnectFailure object>
    __format__ = <built-in method __format__ of ConnectFailure object>
    __ge__ = <method-wrapper '__ge__' of ConnectFailure object>
    __getattribute__ = <method-wrapper '__getattribute__' of ConnectFailure object>
    __gt__ = <method-wrapper '__gt__' of ConnectFailure object>
    __hash__ = <method-wrapper '__hash__' of ConnectFailure object>
    __init__ = <bound method ClientException.__init__ of Connec...te end closed connection without response',))",)>
    __init_subclass__ = <built-in method __init_subclass__ of type object>
    __le__ = <method-wrapper '__le__' of ConnectFailure object>
    __lt__ = <method-wrapper '__lt__' of ConnectFailure object>
    __module__ = 'keystoneauth1.exceptions.connection'
    __ne__ = <method-wrapper '__ne__' of ConnectFailure object>
    __new__ = <built-in method __new__ of type object>
    __reduce__ = <built-in method __reduce__ of ConnectFailure object>
    __reduce_ex__ = <built-in method __reduce_ex__ of ConnectFailure object>
    __repr__ = <method-wrapper '__repr__' of ConnectFailure object>
    __setattr__ = <method-wrapper '__setattr__' of ConnectFailure object>
    __setstate__ = <built-in method __setstate__ of ConnectFailure object>
    __sizeof__ = <built-in method __sizeof__ of ConnectFailure object>
    __str__ = <method-wrapper '__str__' of ConnectFailure object>
    __subclasshook__ = <built-in method __subclasshook__ of type object>
    __suppress_context__ = False
    __traceback__ = <traceback object>
    __weakref__ = None
    args = ("Unable to establish connection to http://192.168...Remote end closed connection without response',))",)
    message = "Unable to establish connection to http://192.168...Remote end closed connection without response',))"
    with_traceback = <built-in method with_traceback of ConnectFailure object>

The above is a description of an error in a Python program.  Here is
the original traceback:

Traceback (most recent call last):
  File "/usr/local/lib/python3.6/site-packages/urllib3/connectionpool.py", line 672, in urlopen
    chunked=chunked,
  File "/usr/local/lib/python3.6/site-packages/urllib3/connectionpool.py", line 421, in _make_request
    six.raise_from(e, None)
  File "<string>", line 3, in raise_from
  File "/usr/local/lib/python3.6/site-packages/urllib3/connectionpool.py", line 416, in _make_request
    httplib_response = conn.getresponse()
  File "/usr/lib64/python3.6/http/client.py", line 1346, in getresponse
    response.begin()
  File "/usr/lib64/python3.6/http/client.py", line 307, in begin
    version, status, reason = self._read_status()
  File "/usr/lib64/python3.6/http/client.py", line 276, in _read_status
    raise RemoteDisconnected("Remote end closed connection without"
http.client.RemoteDisconnected: Remote end closed connection without response

During handling of the above exception, another exception occurred:

Traceback (most recent call last):
  File "/usr/local/lib/python3.6/site-packages/requests/adapters.py", line 449, in send
    timeout=timeout
  File "/usr/local/lib/python3.6/site-packages/urllib3/connectionpool.py", line 720, in urlopen
    method, url, error=e, _pool=self, _stacktrace=sys.exc_info()[2]
  File "/usr/local/lib/python3.6/site-packages/urllib3/util/retry.py", line 400, in increment
    raise six.reraise(type(error), error, _stacktrace)
  File "/usr/local/lib/python3.6/site-packages/urllib3/packages/six.py", line 734, in reraise
    raise value.with_traceback(tb)
  File "/usr/local/lib/python3.6/site-packages/urllib3/connectionpool.py", line 672, in urlopen
    chunked=chunked,
  File "/usr/local/lib/python3.6/site-packages/urllib3/connectionpool.py", line 421, in _make_request
    six.raise_from(e, None)
  File "<string>", line 3, in raise_from
  File "/usr/local/lib/python3.6/site-packages/urllib3/connectionpool.py", line 416, in _make_request
    httplib_response = conn.getresponse()
  File "/usr/lib64/python3.6/http/client.py", line 1346, in getresponse
    response.begin()
  File "/usr/lib64/python3.6/http/client.py", line 307, in begin
    version, status, reason = self._read_status()
  File "/usr/lib64/python3.6/http/client.py", line 276, in _read_status
    raise RemoteDisconnected("Remote end closed connection without"
urllib3.exceptions.ProtocolError: ('Connection aborted.', RemoteDisconnected('Remote end closed connection without response',))

During handling of the above exception, another exception occurred:

Traceback (most recent call last):
  File "/usr/local/lib/python3.6/site-packages/keystoneauth1/session.py", line 1004, in _send_request
    resp = self.session.request(method, url, **kwargs)
  File "/usr/local/lib/python3.6/site-packages/requests/sessions.py", line 533, in request
    resp = self.send(prep, **send_kwargs)
  File "/usr/local/lib/python3.6/site-packages/requests/sessions.py", line 646, in send
    r = adapter.send(request, **kwargs)
  File "/usr/local/lib/python3.6/site-packages/requests/adapters.py", line 498, in send
    raise ConnectionError(err, request=request)
requests.exceptions.ConnectionError: ('Connection aborted.', RemoteDisconnected('Remote end closed connection without response',))

During handling of the above exception, another exception occurred:

Traceback (most recent call last):
  File "/contrail-test/tcutils/wrappers.py", line 82, in wrapper
    result = function(self, *args, **kwargs)
  File "/contrail-test/scripts/vm_regression/test_vm.py", line 2800, in test_vm_file_trf_scp_tests
    orch=self.orchestrator)
  File "/contrail-test/common/base.py", line 292, in create_vm
    **kwargs)
  File "/contrail-test/common/base.py", line 265, in create_only_vm
    vm_obj.setUp()
  File "/contrail-test/fixtures/vm_test.py", line 209, in setUp
    self.create()
  File "/contrail-test/fixtures/vm_test.py", line 262, in create
    fixed_ips=self.fixed_ips)
  File "/contrail-test/fixtures/openstack.py", line 140, in create_vm
    return self.nova_h.create_vm(vm_name=vm_name, image_name=image_name, vn_ids=vn_ids, **kwargs)
  File "/contrail-test/fixtures/nova_test.py", line 617, in create_vm
    min_count=count, max_count=count, userdata=userdata)
  File "/usr/local/lib/python3.6/site-packages/novaclient/v2/servers.py", line 1481, in create
    return self._boot(response_key, *boot_args, **boot_kwargs)
  File "/usr/local/lib/python3.6/site-packages/novaclient/v2/servers.py", line 846, in _boot
    return_raw=return_raw, **kwargs)
  File "/usr/local/lib/python3.6/site-packages/novaclient/base.py", line 364, in _create
    resp, body = self.api.client.post(url, body=body)
  File "/usr/local/lib/python3.6/site-packages/keystoneauth1/adapter.py", line 392, in post
    return self.request(url, 'POST', **kwargs)
  File "/usr/local/lib/python3.6/site-packages/novaclient/client.py", line 72, in request
    **kwargs)
  File "/usr/local/lib/python3.6/site-packages/keystoneauth1/adapter.py", line 545, in request
    resp = super(LegacyJsonAdapter, self).request(*args, **kwargs)
  File "/usr/local/lib/python3.6/site-packages/keystoneauth1/adapter.py", line 248, in request
    return self.session.request(url, method, **kwargs)
  File "/usr/local/lib/python3.6/site-packages/keystoneauth1/session.py", line 913, in request
    resp = send(**kwargs)
  File "/usr/local/lib/python3.6/site-packages/keystoneauth1/session.py", line 1020, in _send_request
    raise exceptions.ConnectFailure(msg)
keystoneauth1.exceptions.connection.ConnectFailure: Unable to establish connection to http://192.168.7.12:8774/v2.1/servers: ('Connection aborted.', RemoteDisconnected('Remote end closed connection without response',))



2021-02-22 05:07:35,454 - DEBUG - No XMPP flaps were noticed during the test
2021-02-22 05:07:35,454 - INFO - 
2021-02-22 05:07:35,454 - INFO - END TEST : test_vm_file_trf_scp_tests : FAILED[0:01:36]
2021-02-22 05:07:35,455 - INFO - --------------------------------------------------------------------------------
2021-02-22 05:07:37,077 - INFO - Deleted project: ctest-TestBasicVMVNx-82901118, ID : 4d0e2cb6-0f42-413b-b1f7-a63e7971f1eb 
2021-02-22 05:25:02,600 - INFO - Reading existing Domain with UUID f27c063f-c6c4-434f-a616-97e72e0043e5
2021-02-22 05:25:02,699 - INFO - Using existing domain ['admin_domain'](f27c063f-c6c4-434f-a616-97e72e0043e5)
2021-02-22 05:25:03,049 - INFO - Project ctest-TestBasicVMVNx-24391839 not found, creating it
2021-02-22 05:25:03,606 - INFO - Created Project:ctest-TestBasicVMVNx-24391839, ID : 199ef226-68c4-45fc-a228-dcd628333a97 
2021-02-22 05:25:06,809 - INFO - ================================================================================
2021-02-22 05:25:06,809 - INFO - STARTING TEST    : test_vm_file_trf_scp_tests
2021-02-22 05:25:06,809 - INFO - TEST DESCRIPTION : 
        Description: Test to validate File Transfer using scp between VMs. Files of different sizes.
        Test steps:
                1. Creating vm's - vm1 and vm2 and a Vn - vn222
                2. Transfer file from vm1 to vm2 with diferrent file sizes using scp
                3. file sizes - 64,1202,2210,10000
                4. verify files present in vm2 match with the size of the file sent.
        Pass criteria: File in vm2 should match with the transferred file size from vm1

        Maintainer : ganeshahv@juniper.net
        
2021-02-22 05:25:08,182 - DEBUG - Nothing to compare xmpp stats {'192.168.7.19': {'192.168.27.20': '0', '192.168.27.34': '0'}, '192.168.7.9': {'192.168.27.20': '0', '192.168.27.34': '0'}} with
2021-02-22 05:25:08,182 - INFO - Initial checks done. Running the testcase now
2021-02-22 05:25:08,183 - INFO - 
2021-02-22 05:26:40,468 - ERROR - ConnectFailure
Python 3.6.8: /usr/bin/python3
Mon Feb 22 05:26:39 2021

A problem occurred in a Python script.  Here is the sequence of
function calls leading up to the error, in the order they occurred.

 /contrail-test/tcutils/wrappers.py in wrapper(self=<scripts.vm_regression.test_vm.TestBasicVMVNx.te...ty,vcenter_compute,vrouter_gw] id=0x7ff919e89b00>, *args=(), **kwargs={})
   80             log.info('Initial checks done. Running the testcase now')
   81             log.info('')
   82             result = function(self, *args, **kwargs)
   83             if self.inputs.upgrade:
   84                 pid = os.getpid()
result = None
function = <function TestBasicVMVNx.test_vm_file_trf_scp_tests>
self = <scripts.vm_regression.test_vm.TestBasicVMVNx.te...ty,vcenter_compute,vrouter_gw] id=0x7ff919e89b00>
args = ()
kwargs = {}

 /contrail-test/scripts/vm_regression/test_vm.py in test_vm_file_trf_scp_tests(self=<scripts.vm_regression.test_vm.TestBasicVMVNx.te...ty,vcenter_compute,vrouter_gw] id=0x7ff919e89b00>)
 2795         cmd_to_sync = [x]
 2796         create_result = True
 2797         vn_fixture = self.create_vn(orch=self.orchestrator)
 2798         vm1_fixture = self.create_vm(vn_fixture=vn_fixture,
 2799             image_name='ubuntu',
vn_fixture undefined
self = <scripts.vm_regression.test_vm.TestBasicVMVNx.te...ty,vcenter_compute,vrouter_gw] id=0x7ff919e89b00>
self.create_vn = <bound method GenericTestBase.create_vn of <scri...y,vcenter_compute,vrouter_gw] id=0x7ff919e89b00>>
orch undefined
self.orchestrator = <openstack.OpenstackOrchestrator object>

 /contrail-test/common/base.py in create_vn(self=<scripts.vm_regression.test_vm.TestBasicVMVNx.te...ty,vcenter_compute,vrouter_gw] id=0x7ff919e89b00>, vn_name=None, vn_subnets=None, cleanup=True, **kwargs={'orch': <openstack.OpenstackOrchestrator object>})
  202         vn_fixture = self.create_only_vn(vn_name=vn_name,
  203                                      vn_subnets=vn_subnets,
  204                                      **kwargs)
  205         if cleanup:
  206             self.addCleanup(vn_fixture.cleanUp)
kwargs = {'orch': <openstack.OpenstackOrchestrator object>}

 /contrail-test/common/base.py in create_only_vn(cls=<class 'scripts.vm_regression.test_vm.TestBasicVMVNx'>, vn_name='ctest-vn-62065493', vn_subnets=None, **kwargs={'orch': <openstack.OpenstackOrchestrator object>})
  195                       subnets=vn_subnets,
  196                       **kwargs)
  197         vn_fixture.setUp()
  198         return vn_fixture
  199     # end create_only_vn
vn_fixture = <vn_test.VNFixture object>
vn_fixture.setUp = <bound method VNFixture.setUp of <vn_test.VNFixture object>>

 /contrail-test/fixtures/vn_test.py in setUp(self=<vn_test.VNFixture object>)
  442     def setUp(self):
  443         super(VNFixture, self).setUp()
  444         self.create()
  445 
  446     def create(self):
self = <vn_test.VNFixture object>
self.create = <bound method VNFixture.create of <vn_test.VNFixture object>>

 /contrail-test/fixtures/vn_test.py in create(self=<vn_test.VNFixture object>)
  455             self._create_vn_api(self.vn_name, self.project_obj)
  456         else:
  457             self._create_vn_orch()
  458         if not self.obj:
  459              self.logger.debug('VN %s not present' % (self.vn_name))
self = <vn_test.VNFixture object>
self._create_vn_orch = <bound method VNFixture._create_vn_orch of <vn_test.VNFixture object>>

 /contrail-test/fixtures/vn_test.py in _create_vn_orch(self=<vn_test.VNFixture object>)
  313                                                 sriov_provider_network=self.sriov_provider_network,
  314                                                 disable_gateway=self.disable_gateway,
  315                                                 dns_nameservers_list=self.dns_nameservers_list)
  316                 if self.obj:
  317                     self.logger.info('Created VN %s' %(self.vn_name))
dns_nameservers_list undefined
self = <vn_test.VNFixture object>
self.dns_nameservers_list = None

 /contrail-test/fixtures/openstack.py in create_vn(self=<openstack.OpenstackOrchestrator object>, name='ctest-vn-62065493', subnets=[{'cidr': '133.230.26.64/26'}], option='orch', **kwargs={'disable_gateway': False, 'dns_nameservers_list': None, 'enable_dhcp': True, 'ipam_fq_name': ['default-domain', 'default-project', 'default-network-ipam'], 'router_external': False, 'shared': False, 'sriov_enable': False, 'sriov_provider_network': None, 'sriov_vlan': None})
  184 
  185    def create_vn(self, name, subnets, option='orch', **kwargs):
  186        return self.quantum_h.create_network(name, subnets, **kwargs)
  187 
  188    def delete_vn(self, vn_obj, option='orch', **kwargs):
self = <openstack.OpenstackOrchestrator object>
self.quantum_h = <quantum_test.QuantumHelper object>
self.quantum_h.create_network = <bound method QuantumHelper.create_network of <quantum_test.QuantumHelper object>>
name = 'ctest-vn-62065493'
subnets = [{'cidr': '133.230.26.64/26'}]
kwargs = {'disable_gateway': False, 'dns_nameservers_list': None, 'enable_dhcp': True, 'ipam_fq_name': ['default-domain', 'default-project', 'default-network-ipam'], 'router_external': False, 'shared': False, 'sriov_enable': False, 'sriov_provider_network': None, 'sriov_vlan': None}

 /contrail-test/fixtures/quantum_test.py in create_network(self=<quantum_test.QuantumHelper object>, vn_name='ctest-vn-62065493', vn_subnets=[{'cidr': '133.230.26.64/26'}], ipam_fq_name=['default-domain', 'default-project', 'default-network-ipam'], shared=False, router_external=False, enable_dhcp=True, sriov_enable=False, sriov_vlan=None, sriov_provider_network=None, dns_nameservers_list=None, disable_gateway=False)
   99                 net_req['provider:physical_network'] = sriov_provider_network
  100                 net_req['provider:segmentation_id'] = sriov_vlan
  101             net_rsp = self.obj.create_network({'network': net_req})
  102             self.logger.debug('Response for create_network : ' + repr(net_rsp))
  103 
net_rsp undefined
self = <quantum_test.QuantumHelper object>
self.obj = <neutronclient.v2_0.client.Client object>
self.obj.create_network = <bound method Client.create_network of <neutronclient.v2_0.client.Client object>>
net_req = {'name': 'ctest-vn-62065493'}

 /usr/local/lib/python3.6/site-packages/neutronclient/v2_0/client.py in create_network(self=<neutronclient.v2_0.client.Client object>, body={'network': {'name': 'ctest-vn-62065493'}})
  824     def create_network(self, body=None):
  825         """Creates a new network."""
  826         return self.post(self.networks_path, body=body)
  827 
  828     def update_network(self, network, body=None, revision_number=None):
self = <neutronclient.v2_0.client.Client object>
self.post = <bound method ClientBase.post of <neutronclient.v2_0.client.Client object>>
self.networks_path = '/networks'
body = {'network': {'name': 'ctest-vn-62065493'}}

 /usr/local/lib/python3.6/site-packages/neutronclient/v2_0/client.py in post(self=<neutronclient.v2_0.client.Client object>, action='/networks', body={'network': {'name': 'ctest-vn-62065493'}}, headers=None, params=None)
  357         # Do not retry POST requests to avoid the orphan objects problem.
  358         return self.do_request("POST", action, body=body,
  359                                headers=headers, params=params)
  360 
  361     def put(self, action, body=None, headers=None, params=None):
headers = None
params = None

 /usr/local/lib/python3.6/site-packages/neutronclient/v2_0/client.py in do_request(self=<neutronclient.v2_0.client.Client object>, method='POST', action='/v2.0/networks', body='{"network": {"name": "ctest-vn-62065493"}}', headers=None, params=None)
  280 
  281         resp, replybody = self.httpclient.do_request(action, method, body=body,
  282                                                      headers=headers)
  283 
  284         status_code = resp.status_code
headers = None

 /usr/local/lib/python3.6/site-packages/neutronclient/client.py in do_request(self=<neutronclient.client.SessionClient object>, url='/v2.0/networks', method='POST', **kwargs={'authenticated': True, 'body': '{"network": {"name": "ctest-vn-62065493"}}', 'headers': None})
  338         kwargs.setdefault('authenticated', True)
  339         self._check_uri_length(url)
  340         return self.request(url, method, **kwargs)
  341 
  342     @property
self = <neutronclient.client.SessionClient object>
self.request = <bound method SessionClient.request of <neutronclient.client.SessionClient object>>
url = '/v2.0/networks'
method = 'POST'
kwargs = {'authenticated': True, 'body': '{"network": {"name": "ctest-vn-62065493"}}', 'headers': None}

 /usr/local/lib/python3.6/site-packages/neutronclient/client.py in request(self=<neutronclient.client.SessionClient object>, *args=('/v2.0/networks', 'POST'), **kwargs={'authenticated': True, 'data': '{"network": {"name": "ctest-vn-62065493"}}', 'headers': {'Accept': 'application/json', 'Content-Type': 'application/json', 'User-Agent': 'python-neutronclient', 'X-Auth-Token': 'cf4482ef874c4718badfbe895374d61e'}, 'raise_exc': False})
  326 
  327         kwargs['headers'] = headers
  328         resp = super(SessionClient, self).request(*args, **kwargs)
  329         return resp, resp.text
  330 
resp undefined
builtinsuper = <class 'super'>
global SessionClient = <class 'neutronclient.client.SessionClient'>
self = <neutronclient.client.SessionClient object>
).request = <bound method SessionClient.request of <neutronclient.client.SessionClient object>>
args = ('/v2.0/networks', 'POST')
kwargs = {'authenticated': True, 'data': '{"network": {"name": "ctest-vn-62065493"}}', 'headers': {'Accept': 'application/json', 'Content-Type': 'application/json', 'User-Agent': 'python-neutronclient', 'X-Auth-Token': 'cf4482ef874c4718badfbe895374d61e'}, 'raise_exc': False}

 /usr/local/lib/python3.6/site-packages/keystoneauth1/adapter.py in request(self=<neutronclient.client.SessionClient object>, url='/v2.0/networks', method='POST', **kwargs={'authenticated': True, 'data': '{"network": {"name": "ctest-vn-62065493"}}', 'endpoint_filter': {'interface': 'public', 'region_name': 'RegionOne', 'service_type': 'network'}, 'headers': {'Accept': 'application/json', 'Content-Type': 'application/json', 'User-Agent': 'python-neutronclient', 'X-Auth-Token': 'cf4482ef874c4718badfbe895374d61e'}, 'raise_exc': False, 'rate_semaphore': <keystoneauth1._fair_semaphore.FairSemaphore object>, 'user_agent': 'python-neutronclient'})
  246             kwargs.setdefault('raise_exc', self.raise_exc)
  247 
  248         return self.session.request(url, method, **kwargs)
  249 
  250     def get_token(self, auth=None):
self = <neutronclient.client.SessionClient object>
self.session = <keystoneauth1.session.Session object>
self.session.request = <bound method Session.request of <keystoneauth1.session.Session object>>
url = '/v2.0/networks'
method = 'POST'
kwargs = {'authenticated': True, 'data': '{"network": {"name": "ctest-vn-62065493"}}', 'endpoint_filter': {'interface': 'public', 'region_name': 'RegionOne', 'service_type': 'network'}, 'headers': {'Accept': 'application/json', 'Content-Type': 'application/json', 'User-Agent': 'python-neutronclient', 'X-Auth-Token': 'cf4482ef874c4718badfbe895374d61e'}, 'raise_exc': False, 'rate_semaphore': <keystoneauth1._fair_semaphore.FairSemaphore object>, 'user_agent': 'python-neutronclient'}

 /usr/local/lib/python3.6/site-packages/keystoneauth1/session.py in request(self=<keystoneauth1.session.Session object>, url='http://192.168.7.31:9696/v2.0/networks', method='POST', json=None, original_ip=None, user_agent='python-neutronclient', redirect=30, authenticated=True, endpoint_filter={'interface': 'public', 'region_name': 'RegionOne', 'service_type': 'network'}, auth=None, requests_auth=None, raise_exc=False, allow_reauth=True, log=True, endpoint_override=None, connect_retries=0, logger=<Logger keystoneauth.session (WARNING)>, allow=None, client_name=None, client_version=None, microversion=None, microversion_service_type=None, status_code_retries=0, retriable_status_codes=[503], rate_semaphore=<keystoneauth1._fair_semaphore.FairSemaphore object>, global_request_id=None, connect_retry_delay=None, status_code_retry_delay=None, **kwargs={'allow_redirects': False, 'cert': (None, None), 'data': '{"network": {"name": "ctest-vn-62065493"}}', 'headers': {'Accept': 'application/json', 'Content-Type': 'application/json', 'User-Agent': 'python-neutronclient', 'X-Auth-Token': 'cf4482ef874c4718badfbe895374d61e'}, 'verify': False})
  911                 kwargs.update(connection_params)
  912 
  913         resp = send(**kwargs)
  914 
  915         # log callee and caller request-id for each api call
resp undefined
send = functools.partial(<bound method Session._send_re...auth1.session._Retries object at 0x7ff91852dc50>)
kwargs = {'allow_redirects': False, 'cert': (None, None), 'data': '{"network": {"name": "ctest-vn-62065493"}}', 'headers': {'Accept': 'application/json', 'Content-Type': 'application/json', 'User-Agent': 'python-neutronclient', 'X-Auth-Token': 'cf4482ef874c4718badfbe895374d61e'}, 'verify': False}

 /usr/local/lib/python3.6/site-packages/keystoneauth1/session.py in _send_request(self=<keystoneauth1.session.Session object>, url='http://192.168.7.31:9696/v2.0/networks', method='POST', redirect=30, log=True, logger=<Logger keystoneauth.session (WARNING)>, split_loggers=None, connect_retries=0, status_code_retries=0, retriable_status_codes=[503], rate_semaphore=<keystoneauth1._fair_semaphore.FairSemaphore object>, connect_retry_delays=<keystoneauth1.session._Retries object>, status_code_retry_delays=<keystoneauth1.session._Retries object>, **kwargs={'allow_redirects': False, 'cert': (None, None), 'data': '{"network": {"name": "ctest-vn-62065493"}}', 'headers': {'Accept': 'application/json', 'Content-Type': 'application/json', 'User-Agent': 'python-neutronclient', 'X-Auth-Token': 'cf4482ef874c4718badfbe895374d61e'}, 'verify': False})
 1018                 # and firewall blocking.
 1019                 msg = 'Unable to establish connection to %s: %s' % (url, e)
 1020                 raise exceptions.ConnectFailure(msg)
 1021             except requests.exceptions.RequestException as e:
 1022                 msg = 'Unexpected exception for %(url)s: %(error)s' % {
global exceptions = <module 'keystoneauth1.exceptions' from '/usr/lo...e-packages/keystoneauth1/exceptions/__init__.py'>
exceptions.ConnectFailure = <class 'keystoneauth1.exceptions.connection.ConnectFailure'>
msg = "Unable to establish connection to http://192.168...Remote end closed connection without response',))"
ConnectFailure: Unable to establish connection to http://192.168.7.31:9696/v2.0/networks: ('Connection aborted.', RemoteDisconnected('Remote end closed connection without response',))
    __cause__ = None
    __class__ = <class 'keystoneauth1.exceptions.connection.ConnectFailure'>
    __context__ = ConnectionError(ProtocolError('Connection aborte...mote end closed connection without response',)),)
    __delattr__ = <method-wrapper '__delattr__' of ConnectFailure object>
    __dict__ = {'message': "Unable to establish connection to http://192.168...Remote end closed connection without response',))"}
    __dir__ = <built-in method __dir__ of ConnectFailure object>
    __doc__ = None
    __eq__ = <method-wrapper '__eq__' of ConnectFailure object>
    __format__ = <built-in method __format__ of ConnectFailure object>
    __ge__ = <method-wrapper '__ge__' of ConnectFailure object>
    __getattribute__ = <method-wrapper '__getattribute__' of ConnectFailure object>
    __gt__ = <method-wrapper '__gt__' of ConnectFailure object>
    __hash__ = <method-wrapper '__hash__' of ConnectFailure object>
    __init__ = <bound method ClientException.__init__ of Connec...te end closed connection without response',))",)>
    __init_subclass__ = <built-in method __init_subclass__ of type object>
    __le__ = <method-wrapper '__le__' of ConnectFailure object>
    __lt__ = <method-wrapper '__lt__' of ConnectFailure object>
    __module__ = 'keystoneauth1.exceptions.connection'
    __ne__ = <method-wrapper '__ne__' of ConnectFailure object>
    __new__ = <built-in method __new__ of type object>
    __reduce__ = <built-in method __reduce__ of ConnectFailure object>
    __reduce_ex__ = <built-in method __reduce_ex__ of ConnectFailure object>
    __repr__ = <method-wrapper '__repr__' of ConnectFailure object>
    __setattr__ = <method-wrapper '__setattr__' of ConnectFailure object>
    __setstate__ = <built-in method __setstate__ of ConnectFailure object>
    __sizeof__ = <built-in method __sizeof__ of ConnectFailure object>
    __str__ = <method-wrapper '__str__' of ConnectFailure object>
    __subclasshook__ = <built-in method __subclasshook__ of type object>
    __suppress_context__ = False
    __traceback__ = <traceback object>
    __weakref__ = None
    args = ("Unable to establish connection to http://192.168...Remote end closed connection without response',))",)
    message = "Unable to establish connection to http://192.168...Remote end closed connection without response',))"
    with_traceback = <built-in method with_traceback of ConnectFailure object>

The above is a description of an error in a Python program.  Here is
the original traceback:

Traceback (most recent call last):
  File "/usr/local/lib/python3.6/site-packages/urllib3/connectionpool.py", line 672, in urlopen
    chunked=chunked,
  File "/usr/local/lib/python3.6/site-packages/urllib3/connectionpool.py", line 421, in _make_request
    six.raise_from(e, None)
  File "<string>", line 3, in raise_from
  File "/usr/local/lib/python3.6/site-packages/urllib3/connectionpool.py", line 416, in _make_request
    httplib_response = conn.getresponse()
  File "/usr/lib64/python3.6/http/client.py", line 1346, in getresponse
    response.begin()
  File "/usr/lib64/python3.6/http/client.py", line 307, in begin
    version, status, reason = self._read_status()
  File "/usr/lib64/python3.6/http/client.py", line 276, in _read_status
    raise RemoteDisconnected("Remote end closed connection without"
http.client.RemoteDisconnected: Remote end closed connection without response

During handling of the above exception, another exception occurred:

Traceback (most recent call last):
  File "/usr/local/lib/python3.6/site-packages/requests/adapters.py", line 449, in send
    timeout=timeout
  File "/usr/local/lib/python3.6/site-packages/urllib3/connectionpool.py", line 720, in urlopen
    method, url, error=e, _pool=self, _stacktrace=sys.exc_info()[2]
  File "/usr/local/lib/python3.6/site-packages/urllib3/util/retry.py", line 400, in increment
    raise six.reraise(type(error), error, _stacktrace)
  File "/usr/local/lib/python3.6/site-packages/urllib3/packages/six.py", line 734, in reraise
    raise value.with_traceback(tb)
  File "/usr/local/lib/python3.6/site-packages/urllib3/connectionpool.py", line 672, in urlopen
    chunked=chunked,
  File "/usr/local/lib/python3.6/site-packages/urllib3/connectionpool.py", line 421, in _make_request
    six.raise_from(e, None)
  File "<string>", line 3, in raise_from
  File "/usr/local/lib/python3.6/site-packages/urllib3/connectionpool.py", line 416, in _make_request
    httplib_response = conn.getresponse()
  File "/usr/lib64/python3.6/http/client.py", line 1346, in getresponse
    response.begin()
  File "/usr/lib64/python3.6/http/client.py", line 307, in begin
    version, status, reason = self._read_status()
  File "/usr/lib64/python3.6/http/client.py", line 276, in _read_status
    raise RemoteDisconnected("Remote end closed connection without"
urllib3.exceptions.ProtocolError: ('Connection aborted.', RemoteDisconnected('Remote end closed connection without response',))

During handling of the above exception, another exception occurred:

Traceback (most recent call last):
  File "/usr/local/lib/python3.6/site-packages/keystoneauth1/session.py", line 1004, in _send_request
    resp = self.session.request(method, url, **kwargs)
  File "/usr/local/lib/python3.6/site-packages/requests/sessions.py", line 533, in request
    resp = self.send(prep, **send_kwargs)
  File "/usr/local/lib/python3.6/site-packages/requests/sessions.py", line 646, in send
    r = adapter.send(request, **kwargs)
  File "/usr/local/lib/python3.6/site-packages/requests/adapters.py", line 498, in send
    raise ConnectionError(err, request=request)
requests.exceptions.ConnectionError: ('Connection aborted.', RemoteDisconnected('Remote end closed connection without response',))

During handling of the above exception, another exception occurred:

Traceback (most recent call last):
  File "/contrail-test/tcutils/wrappers.py", line 82, in wrapper
    result = function(self, *args, **kwargs)
  File "/contrail-test/scripts/vm_regression/test_vm.py", line 2797, in test_vm_file_trf_scp_tests
    vn_fixture = self.create_vn(orch=self.orchestrator)
  File "/contrail-test/common/base.py", line 204, in create_vn
    **kwargs)
  File "/contrail-test/common/base.py", line 197, in create_only_vn
    vn_fixture.setUp()
  File "/contrail-test/fixtures/vn_test.py", line 444, in setUp
    self.create()
  File "/contrail-test/fixtures/vn_test.py", line 457, in create
    self._create_vn_orch()
  File "/contrail-test/fixtures/vn_test.py", line 315, in _create_vn_orch
    dns_nameservers_list=self.dns_nameservers_list)
  File "/contrail-test/fixtures/openstack.py", line 186, in create_vn
    return self.quantum_h.create_network(name, subnets, **kwargs)
  File "/contrail-test/fixtures/quantum_test.py", line 101, in create_network
    net_rsp = self.obj.create_network({'network': net_req})
  File "/usr/local/lib/python3.6/site-packages/neutronclient/v2_0/client.py", line 826, in create_network
    return self.post(self.networks_path, body=body)
  File "/usr/local/lib/python3.6/site-packages/neutronclient/v2_0/client.py", line 359, in post
    headers=headers, params=params)
  File "/usr/local/lib/python3.6/site-packages/neutronclient/v2_0/client.py", line 282, in do_request
    headers=headers)
  File "/usr/local/lib/python3.6/site-packages/neutronclient/client.py", line 340, in do_request
    return self.request(url, method, **kwargs)
  File "/usr/local/lib/python3.6/site-packages/neutronclient/client.py", line 328, in request
    resp = super(SessionClient, self).request(*args, **kwargs)
  File "/usr/local/lib/python3.6/site-packages/keystoneauth1/adapter.py", line 248, in request
    return self.session.request(url, method, **kwargs)
  File "/usr/local/lib/python3.6/site-packages/keystoneauth1/session.py", line 913, in request
    resp = send(**kwargs)
  File "/usr/local/lib/python3.6/site-packages/keystoneauth1/session.py", line 1020, in _send_request
    raise exceptions.ConnectFailure(msg)
keystoneauth1.exceptions.connection.ConnectFailure: Unable to establish connection to http://192.168.7.31:9696/v2.0/networks: ('Connection aborted.', RemoteDisconnected('Remote end closed connection without response',))



2021-02-22 05:26:40,504 - DEBUG - No XMPP flaps were noticed during the test
2021-02-22 05:26:40,504 - INFO - 
2021-02-22 05:26:40,505 - INFO - END TEST : test_vm_file_trf_scp_tests : FAILED[0:01:34]
2021-02-22 05:26:40,505 - INFO - --------------------------------------------------------------------------------
2021-02-22 05:26:42,845 - INFO - Deleted project: ctest-TestBasicVMVNx-24391839, ID : 199ef226-68c4-45fc-a228-dcd628333a97 
2021-02-23 05:56:46,151 - INFO - Reading existing Domain with UUID f27c063f-c6c4-434f-a616-97e72e0043e5
2021-02-23 05:56:46,182 - INFO - Using existing domain ['admin_domain'](f27c063f-c6c4-434f-a616-97e72e0043e5)
2021-02-23 05:56:46,529 - INFO - Project ctest-TestBasicVMVNx-65658814 not found, creating it
2021-02-23 05:56:47,242 - INFO - Created Project:ctest-TestBasicVMVNx-65658814, ID : 4b44d591-c0cd-48b8-adc0-3d919a001632 
2021-02-23 05:56:51,158 - INFO - ================================================================================
2021-02-23 05:56:51,159 - INFO - STARTING TEST    : test_vm_file_trf_scp_tests
2021-02-23 05:56:51,159 - INFO - TEST DESCRIPTION : 
        Description: Test to validate File Transfer using scp between VMs. Files of different sizes.
        Test steps:
                1. Creating vm's - vm1 and vm2 and a Vn - vn222
                2. Transfer file from vm1 to vm2 with diferrent file sizes using scp
                3. file sizes - 64,1202,2210,10000
                4. verify files present in vm2 match with the size of the file sent.
        Pass criteria: File in vm2 should match with the transferred file size from vm1

        Maintainer : ganeshahv@juniper.net
        
2021-02-23 05:56:52,531 - DEBUG - Nothing to compare xmpp stats {'192.168.7.19': {'192.168.27.20': '0', '192.168.27.34': '0'}, '192.168.7.9': {'192.168.27.20': '0', '192.168.27.34': '0'}} with
2021-02-23 05:56:52,531 - INFO - Initial checks done. Running the testcase now
2021-02-23 05:56:52,532 - INFO - 
2021-02-23 05:56:54,309 - DEBUG - Response for create_network : {'network': {'status': 'ACTIVE', 'router:external': False, 'subnets': [], 'fq_name': ['admin_domain', 'ctest-TestBasicVMVNx-65658814', 'ctest-vn-29051427'], 'name': 'ctest-vn-29051427', 'admin_state_up': True, 'tenant_id': '4b44d591c0cd48b8adc03d919a001632', 'created_at': None, 'updated_at': None, 'shared': False, 'port_security_enabled': True, 'project_id': '4b44d591c0cd48b8adc03d919a001632', 'id': '96683500-b680-4d2e-9085-3622f13259e8', 'description': ''}}
2021-02-23 05:58:25,645 - ERROR - ConnectFailure
Python 3.6.8: /usr/bin/python3
Tue Feb 23 05:58:24 2021

A problem occurred in a Python script.  Here is the sequence of
function calls leading up to the error, in the order they occurred.

 /contrail-test/tcutils/wrappers.py in wrapper(self=<scripts.vm_regression.test_vm.TestBasicVMVNx.te...ty,vcenter_compute,vrouter_gw] id=0x7f2c532c8c50>, *args=(), **kwargs={})
   80             log.info('Initial checks done. Running the testcase now')
   81             log.info('')
   82             result = function(self, *args, **kwargs)
   83             if self.inputs.upgrade:
   84                 pid = os.getpid()
result = None
function = <function TestBasicVMVNx.test_vm_file_trf_scp_tests>
self = <scripts.vm_regression.test_vm.TestBasicVMVNx.te...ty,vcenter_compute,vrouter_gw] id=0x7f2c532c8c50>
args = ()
kwargs = {}

 /contrail-test/scripts/vm_regression/test_vm.py in test_vm_file_trf_scp_tests(self=<scripts.vm_regression.test_vm.TestBasicVMVNx.te...ty,vcenter_compute,vrouter_gw] id=0x7f2c532c8c50>)
 2795         cmd_to_sync = [x]
 2796         create_result = True
 2797         vn_fixture = self.create_vn(orch=self.orchestrator)
 2798         vm1_fixture = self.create_vm(vn_fixture=vn_fixture,
 2799             image_name='ubuntu',
vn_fixture undefined
self = <scripts.vm_regression.test_vm.TestBasicVMVNx.te...ty,vcenter_compute,vrouter_gw] id=0x7f2c532c8c50>
self.create_vn = <bound method GenericTestBase.create_vn of <scri...y,vcenter_compute,vrouter_gw] id=0x7f2c532c8c50>>
orch undefined
self.orchestrator = <openstack.OpenstackOrchestrator object>

 /contrail-test/common/base.py in create_vn(self=<scripts.vm_regression.test_vm.TestBasicVMVNx.te...ty,vcenter_compute,vrouter_gw] id=0x7f2c532c8c50>, vn_name=None, vn_subnets=None, cleanup=True, **kwargs={'orch': <openstack.OpenstackOrchestrator object>})
  202         vn_fixture = self.create_only_vn(vn_name=vn_name,
  203                                      vn_subnets=vn_subnets,
  204                                      **kwargs)
  205         if cleanup:
  206             self.addCleanup(vn_fixture.cleanUp)
kwargs = {'orch': <openstack.OpenstackOrchestrator object>}

 /contrail-test/common/base.py in create_only_vn(cls=<class 'scripts.vm_regression.test_vm.TestBasicVMVNx'>, vn_name='ctest-vn-29051427', vn_subnets=None, **kwargs={'orch': <openstack.OpenstackOrchestrator object>})
  195                       subnets=vn_subnets,
  196                       **kwargs)
  197         vn_fixture.setUp()
  198         return vn_fixture
  199     # end create_only_vn
vn_fixture = <vn_test.VNFixture object>
vn_fixture.setUp = <bound method VNFixture.setUp of <vn_test.VNFixture object>>

 /contrail-test/fixtures/vn_test.py in setUp(self=<vn_test.VNFixture object>)
  442     def setUp(self):
  443         super(VNFixture, self).setUp()
  444         self.create()
  445 
  446     def create(self):
self = <vn_test.VNFixture object>
self.create = <bound method VNFixture.create of <vn_test.VNFixture object>>

 /contrail-test/fixtures/vn_test.py in create(self=<vn_test.VNFixture object>)
  455             self._create_vn_api(self.vn_name, self.project_obj)
  456         else:
  457             self._create_vn_orch()
  458         if not self.obj:
  459              self.logger.debug('VN %s not present' % (self.vn_name))
self = <vn_test.VNFixture object>
self._create_vn_orch = <bound method VNFixture._create_vn_orch of <vn_test.VNFixture object>>

 /contrail-test/fixtures/vn_test.py in _create_vn_orch(self=<vn_test.VNFixture object>)
  313                                                 sriov_provider_network=self.sriov_provider_network,
  314                                                 disable_gateway=self.disable_gateway,
  315                                                 dns_nameservers_list=self.dns_nameservers_list)
  316                 if self.obj:
  317                     self.logger.info('Created VN %s' %(self.vn_name))
dns_nameservers_list undefined
self = <vn_test.VNFixture object>
self.dns_nameservers_list = None

 /contrail-test/fixtures/openstack.py in create_vn(self=<openstack.OpenstackOrchestrator object>, name='ctest-vn-29051427', subnets=[{'cidr': '42.217.204.64/26', 'enable_dhcp': True, 'ip_version': '4', 'ipam_fq_name': ['default-domain', 'default-project', 'default-network-ipam'], 'network_id': '96683500-b680-4d2e-9085-3622f13259e8'}], option='orch', **kwargs={'disable_gateway': False, 'dns_nameservers_list': None, 'enable_dhcp': True, 'ipam_fq_name': ['default-domain', 'default-project', 'default-network-ipam'], 'router_external': False, 'shared': False, 'sriov_enable': False, 'sriov_provider_network': None, 'sriov_vlan': None})
  184 
  185    def create_vn(self, name, subnets, option='orch', **kwargs):
  186        return self.quantum_h.create_network(name, subnets, **kwargs)
  187 
  188    def delete_vn(self, vn_obj, option='orch', **kwargs):
self = <openstack.OpenstackOrchestrator object>
self.quantum_h = <quantum_test.QuantumHelper object>
self.quantum_h.create_network = <bound method QuantumHelper.create_network of <quantum_test.QuantumHelper object>>
name = 'ctest-vn-29051427'
subnets = [{'cidr': '42.217.204.64/26', 'enable_dhcp': True, 'ip_version': '4', 'ipam_fq_name': ['default-domain', 'default-project', 'default-network-ipam'], 'network_id': '96683500-b680-4d2e-9085-3622f13259e8'}]
kwargs = {'disable_gateway': False, 'dns_nameservers_list': None, 'enable_dhcp': True, 'ipam_fq_name': ['default-domain', 'default-project', 'default-network-ipam'], 'router_external': False, 'shared': False, 'sriov_enable': False, 'sriov_provider_network': None, 'sriov_vlan': None}

 /contrail-test/fixtures/quantum_test.py in create_network(self=<quantum_test.QuantumHelper object>, vn_name='ctest-vn-29051427', vn_subnets=[{'cidr': '42.217.204.64/26', 'enable_dhcp': True, 'ip_version': '4', 'ipam_fq_name': ['default-domain', 'default-project', 'default-network-ipam'], 'network_id': '96683500-b680-4d2e-9085-3622f13259e8'}], ipam_fq_name=['default-domain', 'default-project', 'default-network-ipam'], shared=False, router_external=False, enable_dhcp=True, sriov_enable=False, sriov_vlan=None, sriov_provider_network=None, dns_nameservers_list=None, disable_gateway=False)
  107                 for subnet in vn_subnets:
  108                     net_rsp = self.create_subnet(
  109                         subnet, net_id, ipam_fq_name, enable_dhcp, disable_gateway,dns_nameservers_list)
  110             # end for
  111             return self.obj.show_network(network=net_id)
subnet = {'cidr': '42.217.204.64/26', 'enable_dhcp': True, 'ip_version': '4', 'ipam_fq_name': ['default-domain', 'default-project', 'default-network-ipam'], 'network_id': '96683500-b680-4d2e-9085-3622f13259e8'}
net_id = '96683500-b680-4d2e-9085-3622f13259e8'
ipam_fq_name = ['default-domain', 'default-project', 'default-network-ipam']
enable_dhcp = True
disable_gateway = False
dns_nameservers_list = None

 /contrail-test/fixtures/quantum_test.py in create_subnet(self=<quantum_test.QuantumHelper object>, subnet={'cidr': '42.217.204.64/26', 'enable_dhcp': True, 'ip_version': '4', 'ipam_fq_name': ['default-domain', 'default-project', 'default-network-ipam'], 'network_id': '96683500-b680-4d2e-9085-3622f13259e8'}, net_id='96683500-b680-4d2e-9085-3622f13259e8', ipam_fq_name=['default-domain', 'default-project', 'default-network-ipam'], enable_dhcp=True, disable_gateway=False, dns_nameservers_list=None)
  127            subnet_req['gateway_ip'] = None
  128         try:
  129             subnet_rsp = self.obj.create_subnet({'subnet': subnet_req})
  130             self.logger.debug(
  131                 'Response for create_subnet : ' +
subnet_rsp undefined
self = <quantum_test.QuantumHelper object>
self.obj = <neutronclient.v2_0.client.Client object>
self.obj.create_subnet = <bound method Client.create_subnet of <neutronclient.v2_0.client.Client object>>
subnet_req = {'cidr': '42.217.204.64/26', 'enable_dhcp': True, 'ip_version': '4', 'ipam_fq_name': ['default-domain', 'default-project', 'default-network-ipam'], 'network_id': '96683500-b680-4d2e-9085-3622f13259e8'}

 /usr/local/lib/python3.6/site-packages/neutronclient/v2_0/client.py in create_subnet(self=<neutronclient.v2_0.client.Client object>, body={'subnet': {'cidr': '42.217.204.64/26', 'enable_dhcp': True, 'ip_version': '4', 'ipam_fq_name': ['default-domain', 'default-project', 'default-network-ipam'], 'network_id': '96683500-b680-4d2e-9085-3622f13259e8'}})
  846     def create_subnet(self, body=None):
  847         """Creates a new subnet."""
  848         return self.post(self.subnets_path, body=body)
  849 
  850     def update_subnet(self, subnet, body=None, revision_number=None):
self = <neutronclient.v2_0.client.Client object>
self.post = <bound method ClientBase.post of <neutronclient.v2_0.client.Client object>>
self.subnets_path = '/subnets'
body = {'subnet': {'cidr': '42.217.204.64/26', 'enable_dhcp': True, 'ip_version': '4', 'ipam_fq_name': ['default-domain', 'default-project', 'default-network-ipam'], 'network_id': '96683500-b680-4d2e-9085-3622f13259e8'}}

 /usr/local/lib/python3.6/site-packages/neutronclient/v2_0/client.py in post(self=<neutronclient.v2_0.client.Client object>, action='/subnets', body={'subnet': {'cidr': '42.217.204.64/26', 'enable_dhcp': True, 'ip_version': '4', 'ipam_fq_name': ['default-domain', 'default-project', 'default-network-ipam'], 'network_id': '96683500-b680-4d2e-9085-3622f13259e8'}}, headers=None, params=None)
  357         # Do not retry POST requests to avoid the orphan objects problem.
  358         return self.do_request("POST", action, body=body,
  359                                headers=headers, params=params)
  360 
  361     def put(self, action, body=None, headers=None, params=None):
headers = None
params = None

 /usr/local/lib/python3.6/site-packages/neutronclient/v2_0/client.py in do_request(self=<neutronclient.v2_0.client.Client object>, method='POST', action='/v2.0/subnets', body='{"subnet": {"cidr": "42.217.204.64/26", "network...in", "default-project", "default-network-ipam"]}}', headers=None, params=None)
  280 
  281         resp, replybody = self.httpclient.do_request(action, method, body=body,
  282                                                      headers=headers)
  283 
  284         status_code = resp.status_code
headers = None

 /usr/local/lib/python3.6/site-packages/neutronclient/client.py in do_request(self=<neutronclient.client.SessionClient object>, url='/v2.0/subnets', method='POST', **kwargs={'authenticated': True, 'body': '{"subnet": {"cidr": "42.217.204.64/26", "network...in", "default-project", "default-network-ipam"]}}', 'headers': None})
  338         kwargs.setdefault('authenticated', True)
  339         self._check_uri_length(url)
  340         return self.request(url, method, **kwargs)
  341 
  342     @property
self = <neutronclient.client.SessionClient object>
self.request = <bound method SessionClient.request of <neutronclient.client.SessionClient object>>
url = '/v2.0/subnets'
method = 'POST'
kwargs = {'authenticated': True, 'body': '{"subnet": {"cidr": "42.217.204.64/26", "network...in", "default-project", "default-network-ipam"]}}', 'headers': None}

 /usr/local/lib/python3.6/site-packages/neutronclient/client.py in request(self=<neutronclient.client.SessionClient object>, *args=('/v2.0/subnets', 'POST'), **kwargs={'authenticated': True, 'data': '{"subnet": {"cidr": "42.217.204.64/26", "network...in", "default-project", "default-network-ipam"]}}', 'headers': {'Accept': 'application/json', 'Content-Type': 'application/json', 'User-Agent': 'python-neutronclient', 'X-Auth-Token': '6e407c30e38c4dc09f24efdfc6b0e239'}, 'raise_exc': False})
  326 
  327         kwargs['headers'] = headers
  328         resp = super(SessionClient, self).request(*args, **kwargs)
  329         return resp, resp.text
  330 
resp undefined
builtinsuper = <class 'super'>
global SessionClient = <class 'neutronclient.client.SessionClient'>
self = <neutronclient.client.SessionClient object>
).request = <bound method SessionClient.request of <neutronclient.client.SessionClient object>>
args = ('/v2.0/subnets', 'POST')
kwargs = {'authenticated': True, 'data': '{"subnet": {"cidr": "42.217.204.64/26", "network...in", "default-project", "default-network-ipam"]}}', 'headers': {'Accept': 'application/json', 'Content-Type': 'application/json', 'User-Agent': 'python-neutronclient', 'X-Auth-Token': '6e407c30e38c4dc09f24efdfc6b0e239'}, 'raise_exc': False}

 /usr/local/lib/python3.6/site-packages/keystoneauth1/adapter.py in request(self=<neutronclient.client.SessionClient object>, url='/v2.0/subnets', method='POST', **kwargs={'authenticated': True, 'data': '{"subnet": {"cidr": "42.217.204.64/26", "network...in", "default-project", "default-network-ipam"]}}', 'endpoint_filter': {'interface': 'public', 'region_name': 'RegionOne', 'service_type': 'network'}, 'headers': {'Accept': 'application/json', 'Content-Type': 'application/json', 'User-Agent': 'python-neutronclient', 'X-Auth-Token': '6e407c30e38c4dc09f24efdfc6b0e239'}, 'raise_exc': False, 'rate_semaphore': <keystoneauth1._fair_semaphore.FairSemaphore object>, 'user_agent': 'python-neutronclient'})
  246             kwargs.setdefault('raise_exc', self.raise_exc)
  247 
  248         return self.session.request(url, method, **kwargs)
  249 
  250     def get_token(self, auth=None):
self = <neutronclient.client.SessionClient object>
self.session = <keystoneauth1.session.Session object>
self.session.request = <bound method Session.request of <keystoneauth1.session.Session object>>
url = '/v2.0/subnets'
method = 'POST'
kwargs = {'authenticated': True, 'data': '{"subnet": {"cidr": "42.217.204.64/26", "network...in", "default-project", "default-network-ipam"]}}', 'endpoint_filter': {'interface': 'public', 'region_name': 'RegionOne', 'service_type': 'network'}, 'headers': {'Accept': 'application/json', 'Content-Type': 'application/json', 'User-Agent': 'python-neutronclient', 'X-Auth-Token': '6e407c30e38c4dc09f24efdfc6b0e239'}, 'raise_exc': False, 'rate_semaphore': <keystoneauth1._fair_semaphore.FairSemaphore object>, 'user_agent': 'python-neutronclient'}

 /usr/local/lib/python3.6/site-packages/keystoneauth1/session.py in request(self=<keystoneauth1.session.Session object>, url='http://192.168.7.31:9696/v2.0/subnets', method='POST', json=None, original_ip=None, user_agent='python-neutronclient', redirect=30, authenticated=True, endpoint_filter={'interface': 'public', 'region_name': 'RegionOne', 'service_type': 'network'}, auth=None, requests_auth=None, raise_exc=False, allow_reauth=True, log=True, endpoint_override=None, connect_retries=0, logger=<Logger keystoneauth.session (WARNING)>, allow=None, client_name=None, client_version=None, microversion=None, microversion_service_type=None, status_code_retries=0, retriable_status_codes=[503], rate_semaphore=<keystoneauth1._fair_semaphore.FairSemaphore object>, global_request_id=None, connect_retry_delay=None, status_code_retry_delay=None, **kwargs={'allow_redirects': False, 'cert': (None, None), 'data': '{"subnet": {"cidr": "42.217.204.64/26", "network...in", "default-project", "default-network-ipam"]}}', 'headers': {'Accept': 'application/json', 'Content-Type': 'application/json', 'User-Agent': 'python-neutronclient', 'X-Auth-Token': '6e407c30e38c4dc09f24efdfc6b0e239'}, 'verify': False})
  911                 kwargs.update(connection_params)
  912 
  913         resp = send(**kwargs)
  914 
  915         # log callee and caller request-id for each api call
resp undefined
send = functools.partial(<bound method Session._send_re...auth1.session._Retries object at 0x7f2c537377b8>)
kwargs = {'allow_redirects': False, 'cert': (None, None), 'data': '{"subnet": {"cidr": "42.217.204.64/26", "network...in", "default-project", "default-network-ipam"]}}', 'headers': {'Accept': 'application/json', 'Content-Type': 'application/json', 'User-Agent': 'python-neutronclient', 'X-Auth-Token': '6e407c30e38c4dc09f24efdfc6b0e239'}, 'verify': False}

 /usr/local/lib/python3.6/site-packages/keystoneauth1/session.py in _send_request(self=<keystoneauth1.session.Session object>, url='http://192.168.7.31:9696/v2.0/subnets', method='POST', redirect=30, log=True, logger=<Logger keystoneauth.session (WARNING)>, split_loggers=None, connect_retries=0, status_code_retries=0, retriable_status_codes=[503], rate_semaphore=<keystoneauth1._fair_semaphore.FairSemaphore object>, connect_retry_delays=<keystoneauth1.session._Retries object>, status_code_retry_delays=<keystoneauth1.session._Retries object>, **kwargs={'allow_redirects': False, 'cert': (None, None), 'data': '{"subnet": {"cidr": "42.217.204.64/26", "network...in", "default-project", "default-network-ipam"]}}', 'headers': {'Accept': 'application/json', 'Content-Type': 'application/json', 'User-Agent': 'python-neutronclient', 'X-Auth-Token': '6e407c30e38c4dc09f24efdfc6b0e239'}, 'verify': False})
 1018                 # and firewall blocking.
 1019                 msg = 'Unable to establish connection to %s: %s' % (url, e)
 1020                 raise exceptions.ConnectFailure(msg)
 1021             except requests.exceptions.RequestException as e:
 1022                 msg = 'Unexpected exception for %(url)s: %(error)s' % {
global exceptions = <module 'keystoneauth1.exceptions' from '/usr/lo...e-packages/keystoneauth1/exceptions/__init__.py'>
exceptions.ConnectFailure = <class 'keystoneauth1.exceptions.connection.ConnectFailure'>
msg = "Unable to establish connection to http://192.168...Remote end closed connection without response',))"
ConnectFailure: Unable to establish connection to http://192.168.7.31:9696/v2.0/subnets: ('Connection aborted.', RemoteDisconnected('Remote end closed connection without response',))
    __cause__ = None
    __class__ = <class 'keystoneauth1.exceptions.connection.ConnectFailure'>
    __context__ = ConnectionError(ProtocolError('Connection aborte...mote end closed connection without response',)),)
    __delattr__ = <method-wrapper '__delattr__' of ConnectFailure object>
    __dict__ = {'message': "Unable to establish connection to http://192.168...Remote end closed connection without response',))"}
    __dir__ = <built-in method __dir__ of ConnectFailure object>
    __doc__ = None
    __eq__ = <method-wrapper '__eq__' of ConnectFailure object>
    __format__ = <built-in method __format__ of ConnectFailure object>
    __ge__ = <method-wrapper '__ge__' of ConnectFailure object>
    __getattribute__ = <method-wrapper '__getattribute__' of ConnectFailure object>
    __gt__ = <method-wrapper '__gt__' of ConnectFailure object>
    __hash__ = <method-wrapper '__hash__' of ConnectFailure object>
    __init__ = <bound method ClientException.__init__ of Connec...te end closed connection without response',))",)>
    __init_subclass__ = <built-in method __init_subclass__ of type object>
    __le__ = <method-wrapper '__le__' of ConnectFailure object>
    __lt__ = <method-wrapper '__lt__' of ConnectFailure object>
    __module__ = 'keystoneauth1.exceptions.connection'
    __ne__ = <method-wrapper '__ne__' of ConnectFailure object>
    __new__ = <built-in method __new__ of type object>
    __reduce__ = <built-in method __reduce__ of ConnectFailure object>
    __reduce_ex__ = <built-in method __reduce_ex__ of ConnectFailure object>
    __repr__ = <method-wrapper '__repr__' of ConnectFailure object>
    __setattr__ = <method-wrapper '__setattr__' of ConnectFailure object>
    __setstate__ = <built-in method __setstate__ of ConnectFailure object>
    __sizeof__ = <built-in method __sizeof__ of ConnectFailure object>
    __str__ = <method-wrapper '__str__' of ConnectFailure object>
    __subclasshook__ = <built-in method __subclasshook__ of type object>
    __suppress_context__ = False
    __traceback__ = <traceback object>
    __weakref__ = None
    args = ("Unable to establish connection to http://192.168...Remote end closed connection without response',))",)
    message = "Unable to establish connection to http://192.168...Remote end closed connection without response',))"
    with_traceback = <built-in method with_traceback of ConnectFailure object>

The above is a description of an error in a Python program.  Here is
the original traceback:

Traceback (most recent call last):
  File "/usr/local/lib/python3.6/site-packages/urllib3/connectionpool.py", line 672, in urlopen
    chunked=chunked,
  File "/usr/local/lib/python3.6/site-packages/urllib3/connectionpool.py", line 421, in _make_request
    six.raise_from(e, None)
  File "<string>", line 3, in raise_from
  File "/usr/local/lib/python3.6/site-packages/urllib3/connectionpool.py", line 416, in _make_request
    httplib_response = conn.getresponse()
  File "/usr/lib64/python3.6/http/client.py", line 1346, in getresponse
    response.begin()
  File "/usr/lib64/python3.6/http/client.py", line 307, in begin
    version, status, reason = self._read_status()
  File "/usr/lib64/python3.6/http/client.py", line 276, in _read_status
    raise RemoteDisconnected("Remote end closed connection without"
http.client.RemoteDisconnected: Remote end closed connection without response

During handling of the above exception, another exception occurred:

Traceback (most recent call last):
  File "/usr/local/lib/python3.6/site-packages/requests/adapters.py", line 449, in send
    timeout=timeout
  File "/usr/local/lib/python3.6/site-packages/urllib3/connectionpool.py", line 720, in urlopen
    method, url, error=e, _pool=self, _stacktrace=sys.exc_info()[2]
  File "/usr/local/lib/python3.6/site-packages/urllib3/util/retry.py", line 400, in increment
    raise six.reraise(type(error), error, _stacktrace)
  File "/usr/local/lib/python3.6/site-packages/urllib3/packages/six.py", line 734, in reraise
    raise value.with_traceback(tb)
  File "/usr/local/lib/python3.6/site-packages/urllib3/connectionpool.py", line 672, in urlopen
    chunked=chunked,
  File "/usr/local/lib/python3.6/site-packages/urllib3/connectionpool.py", line 421, in _make_request
    six.raise_from(e, None)
  File "<string>", line 3, in raise_from
  File "/usr/local/lib/python3.6/site-packages/urllib3/connectionpool.py", line 416, in _make_request
    httplib_response = conn.getresponse()
  File "/usr/lib64/python3.6/http/client.py", line 1346, in getresponse
    response.begin()
  File "/usr/lib64/python3.6/http/client.py", line 307, in begin
    version, status, reason = self._read_status()
  File "/usr/lib64/python3.6/http/client.py", line 276, in _read_status
    raise RemoteDisconnected("Remote end closed connection without"
urllib3.exceptions.ProtocolError: ('Connection aborted.', RemoteDisconnected('Remote end closed connection without response',))

During handling of the above exception, another exception occurred:

Traceback (most recent call last):
  File "/usr/local/lib/python3.6/site-packages/keystoneauth1/session.py", line 1004, in _send_request
    resp = self.session.request(method, url, **kwargs)
  File "/usr/local/lib/python3.6/site-packages/requests/sessions.py", line 533, in request
    resp = self.send(prep, **send_kwargs)
  File "/usr/local/lib/python3.6/site-packages/requests/sessions.py", line 646, in send
    r = adapter.send(request, **kwargs)
  File "/usr/local/lib/python3.6/site-packages/requests/adapters.py", line 498, in send
    raise ConnectionError(err, request=request)
requests.exceptions.ConnectionError: ('Connection aborted.', RemoteDisconnected('Remote end closed connection without response',))

During handling of the above exception, another exception occurred:

Traceback (most recent call last):
  File "/contrail-test/tcutils/wrappers.py", line 82, in wrapper
    result = function(self, *args, **kwargs)
  File "/contrail-test/scripts/vm_regression/test_vm.py", line 2797, in test_vm_file_trf_scp_tests
    vn_fixture = self.create_vn(orch=self.orchestrator)
  File "/contrail-test/common/base.py", line 204, in create_vn
    **kwargs)
  File "/contrail-test/common/base.py", line 197, in create_only_vn
    vn_fixture.setUp()
  File "/contrail-test/fixtures/vn_test.py", line 444, in setUp
    self.create()
  File "/contrail-test/fixtures/vn_test.py", line 457, in create
    self._create_vn_orch()
  File "/contrail-test/fixtures/vn_test.py", line 315, in _create_vn_orch
    dns_nameservers_list=self.dns_nameservers_list)
  File "/contrail-test/fixtures/openstack.py", line 186, in create_vn
    return self.quantum_h.create_network(name, subnets, **kwargs)
  File "/contrail-test/fixtures/quantum_test.py", line 109, in create_network
    subnet, net_id, ipam_fq_name, enable_dhcp, disable_gateway,dns_nameservers_list)
  File "/contrail-test/fixtures/quantum_test.py", line 129, in create_subnet
    subnet_rsp = self.obj.create_subnet({'subnet': subnet_req})
  File "/usr/local/lib/python3.6/site-packages/neutronclient/v2_0/client.py", line 848, in create_subnet
    return self.post(self.subnets_path, body=body)
  File "/usr/local/lib/python3.6/site-packages/neutronclient/v2_0/client.py", line 359, in post
    headers=headers, params=params)
  File "/usr/local/lib/python3.6/site-packages/neutronclient/v2_0/client.py", line 282, in do_request
    headers=headers)
  File "/usr/local/lib/python3.6/site-packages/neutronclient/client.py", line 340, in do_request
    return self.request(url, method, **kwargs)
  File "/usr/local/lib/python3.6/site-packages/neutronclient/client.py", line 328, in request
    resp = super(SessionClient, self).request(*args, **kwargs)
  File "/usr/local/lib/python3.6/site-packages/keystoneauth1/adapter.py", line 248, in request
    return self.session.request(url, method, **kwargs)
  File "/usr/local/lib/python3.6/site-packages/keystoneauth1/session.py", line 913, in request
    resp = send(**kwargs)
  File "/usr/local/lib/python3.6/site-packages/keystoneauth1/session.py", line 1020, in _send_request
    raise exceptions.ConnectFailure(msg)
keystoneauth1.exceptions.connection.ConnectFailure: Unable to establish connection to http://192.168.7.31:9696/v2.0/subnets: ('Connection aborted.', RemoteDisconnected('Remote end closed connection without response',))



2021-02-23 05:58:25,685 - DEBUG - No XMPP flaps were noticed during the test
2021-02-23 05:58:25,686 - INFO - 
2021-02-23 05:58:25,686 - INFO - END TEST : test_vm_file_trf_scp_tests : FAILED[0:01:34]
2021-02-23 05:58:25,686 - INFO - --------------------------------------------------------------------------------
2021-02-23 05:58:25,855 - WARNING - Project ctest-TestBasicVMVNx-65658814 still has VNs [{'to': ['admin_domain', 'ctest-TestBasicVMVNx-65658814', 'ctest-vn-29051427'], 'href': 'https://192.168.7.34:8082/virtual-network/96683500-b680-4d2e-9085-3622f13259e8', 'uuid': '96683500-b680-4d2e-9085-3622f13259e8'}] before deletion
2021-02-23 05:58:27,964 - WARNING - Project ctest-TestBasicVMVNx-65658814 still has VNs [{'to': ['admin_domain', 'ctest-TestBasicVMVNx-65658814', 'ctest-vn-29051427'], 'href': 'https://192.168.7.34:8082/virtual-network/96683500-b680-4d2e-9085-3622f13259e8', 'uuid': '96683500-b680-4d2e-9085-3622f13259e8'}] before deletion
2021-02-23 05:58:30,085 - WARNING - Project ctest-TestBasicVMVNx-65658814 still has VNs [{'to': ['admin_domain', 'ctest-TestBasicVMVNx-65658814', 'ctest-vn-29051427'], 'href': 'https://192.168.7.34:8082/virtual-network/96683500-b680-4d2e-9085-3622f13259e8', 'uuid': '96683500-b680-4d2e-9085-3622f13259e8'}] before deletion
2021-02-23 05:58:32,219 - WARNING - Project ctest-TestBasicVMVNx-65658814 still has VNs [{'to': ['admin_domain', 'ctest-TestBasicVMVNx-65658814', 'ctest-vn-29051427'], 'href': 'https://192.168.7.34:8082/virtual-network/96683500-b680-4d2e-9085-3622f13259e8', 'uuid': '96683500-b680-4d2e-9085-3622f13259e8'}] before deletion
2021-02-23 05:58:34,357 - WARNING - Project ctest-TestBasicVMVNx-65658814 still has VNs [{'to': ['admin_domain', 'ctest-TestBasicVMVNx-65658814', 'ctest-vn-29051427'], 'href': 'https://192.168.7.34:8082/virtual-network/96683500-b680-4d2e-9085-3622f13259e8', 'uuid': '96683500-b680-4d2e-9085-3622f13259e8'}] before deletion
2021-02-23 05:58:36,476 - WARNING - Project ctest-TestBasicVMVNx-65658814 still has VNs [{'to': ['admin_domain', 'ctest-TestBasicVMVNx-65658814', 'ctest-vn-29051427'], 'href': 'https://192.168.7.34:8082/virtual-network/96683500-b680-4d2e-9085-3622f13259e8', 'uuid': '96683500-b680-4d2e-9085-3622f13259e8'}] before deletion
2021-02-23 05:58:38,597 - WARNING - Project ctest-TestBasicVMVNx-65658814 still has VNs [{'to': ['admin_domain', 'ctest-TestBasicVMVNx-65658814', 'ctest-vn-29051427'], 'href': 'https://192.168.7.34:8082/virtual-network/96683500-b680-4d2e-9085-3622f13259e8', 'uuid': '96683500-b680-4d2e-9085-3622f13259e8'}] before deletion
2021-02-23 05:58:40,714 - WARNING - Project ctest-TestBasicVMVNx-65658814 still has VNs [{'to': ['admin_domain', 'ctest-TestBasicVMVNx-65658814', 'ctest-vn-29051427'], 'href': 'https://192.168.7.34:8082/virtual-network/96683500-b680-4d2e-9085-3622f13259e8', 'uuid': '96683500-b680-4d2e-9085-3622f13259e8'}] before deletion
2021-02-23 05:58:42,837 - WARNING - Project ctest-TestBasicVMVNx-65658814 still has VNs [{'to': ['admin_domain', 'ctest-TestBasicVMVNx-65658814', 'ctest-vn-29051427'], 'href': 'https://192.168.7.34:8082/virtual-network/96683500-b680-4d2e-9085-3622f13259e8', 'uuid': '96683500-b680-4d2e-9085-3622f13259e8'}] before deletion
2021-02-23 05:58:44,961 - WARNING - Project ctest-TestBasicVMVNx-65658814 still has VNs [{'to': ['admin_domain', 'ctest-TestBasicVMVNx-65658814', 'ctest-vn-29051427'], 'href': 'https://192.168.7.34:8082/virtual-network/96683500-b680-4d2e-9085-3622f13259e8', 'uuid': '96683500-b680-4d2e-9085-3622f13259e8'}] before deletion
2021-02-23 05:58:47,089 - WARNING - Project ctest-TestBasicVMVNx-65658814 still has VNs [{'to': ['admin_domain', 'ctest-TestBasicVMVNx-65658814', 'ctest-vn-29051427'], 'href': 'https://192.168.7.34:8082/virtual-network/96683500-b680-4d2e-9085-3622f13259e8', 'uuid': '96683500-b680-4d2e-9085-3622f13259e8'}] before deletion
2021-02-23 05:58:49,208 - WARNING - Project ctest-TestBasicVMVNx-65658814 still has VNs [{'to': ['admin_domain', 'ctest-TestBasicVMVNx-65658814', 'ctest-vn-29051427'], 'href': 'https://192.168.7.34:8082/virtual-network/96683500-b680-4d2e-9085-3622f13259e8', 'uuid': '96683500-b680-4d2e-9085-3622f13259e8'}] before deletion
2021-02-23 05:58:51,351 - WARNING - Project ctest-TestBasicVMVNx-65658814 still has VNs [{'to': ['admin_domain', 'ctest-TestBasicVMVNx-65658814', 'ctest-vn-29051427'], 'href': 'https://192.168.7.34:8082/virtual-network/96683500-b680-4d2e-9085-3622f13259e8', 'uuid': '96683500-b680-4d2e-9085-3622f13259e8'}] before deletion
2021-02-23 05:58:53,477 - WARNING - Project ctest-TestBasicVMVNx-65658814 still has VNs [{'to': ['admin_domain', 'ctest-TestBasicVMVNx-65658814', 'ctest-vn-29051427'], 'href': 'https://192.168.7.34:8082/virtual-network/96683500-b680-4d2e-9085-3622f13259e8', 'uuid': '96683500-b680-4d2e-9085-3622f13259e8'}] before deletion
2021-02-23 05:58:55,603 - WARNING - Project ctest-TestBasicVMVNx-65658814 still has VNs [{'to': ['admin_domain', 'ctest-TestBasicVMVNx-65658814', 'ctest-vn-29051427'], 'href': 'https://192.168.7.34:8082/virtual-network/96683500-b680-4d2e-9085-3622f13259e8', 'uuid': '96683500-b680-4d2e-9085-3622f13259e8'}] before deletion
2021-02-23 05:58:57,725 - WARNING - Project ctest-TestBasicVMVNx-65658814 still has VNs [{'to': ['admin_domain', 'ctest-TestBasicVMVNx-65658814', 'ctest-vn-29051427'], 'href': 'https://192.168.7.34:8082/virtual-network/96683500-b680-4d2e-9085-3622f13259e8', 'uuid': '96683500-b680-4d2e-9085-3622f13259e8'}] before deletion
2021-02-23 05:58:59,846 - WARNING - Project ctest-TestBasicVMVNx-65658814 still has VNs [{'to': ['admin_domain', 'ctest-TestBasicVMVNx-65658814', 'ctest-vn-29051427'], 'href': 'https://192.168.7.34:8082/virtual-network/96683500-b680-4d2e-9085-3622f13259e8', 'uuid': '96683500-b680-4d2e-9085-3622f13259e8'}] before deletion
2021-02-23 05:59:01,960 - WARNING - Project ctest-TestBasicVMVNx-65658814 still has VNs [{'to': ['admin_domain', 'ctest-TestBasicVMVNx-65658814', 'ctest-vn-29051427'], 'href': 'https://192.168.7.34:8082/virtual-network/96683500-b680-4d2e-9085-3622f13259e8', 'uuid': '96683500-b680-4d2e-9085-3622f13259e8'}] before deletion
2021-02-23 05:59:04,087 - WARNING - Project ctest-TestBasicVMVNx-65658814 still has VNs [{'to': ['admin_domain', 'ctest-TestBasicVMVNx-65658814', 'ctest-vn-29051427'], 'href': 'https://192.168.7.34:8082/virtual-network/96683500-b680-4d2e-9085-3622f13259e8', 'uuid': '96683500-b680-4d2e-9085-3622f13259e8'}] before deletion
2021-02-23 05:59:06,200 - WARNING - Project ctest-TestBasicVMVNx-65658814 still has VNs [{'to': ['admin_domain', 'ctest-TestBasicVMVNx-65658814', 'ctest-vn-29051427'], 'href': 'https://192.168.7.34:8082/virtual-network/96683500-b680-4d2e-9085-3622f13259e8', 'uuid': '96683500-b680-4d2e-9085-3622f13259e8'}] before deletion
2021-02-23 05:59:08,328 - WARNING - Project ctest-TestBasicVMVNx-65658814 still has VNs [{'to': ['admin_domain', 'ctest-TestBasicVMVNx-65658814', 'ctest-vn-29051427'], 'href': 'https://192.168.7.34:8082/virtual-network/96683500-b680-4d2e-9085-3622f13259e8', 'uuid': '96683500-b680-4d2e-9085-3622f13259e8'}] before deletion
2021-02-23 05:59:10,463 - WARNING - Project ctest-TestBasicVMVNx-65658814 still has VNs [{'to': ['admin_domain', 'ctest-TestBasicVMVNx-65658814', 'ctest-vn-29051427'], 'href': 'https://192.168.7.34:8082/virtual-network/96683500-b680-4d2e-9085-3622f13259e8', 'uuid': '96683500-b680-4d2e-9085-3622f13259e8'}] before deletion
2021-02-23 05:59:12,596 - WARNING - Project ctest-TestBasicVMVNx-65658814 still has VNs [{'to': ['admin_domain', 'ctest-TestBasicVMVNx-65658814', 'ctest-vn-29051427'], 'href': 'https://192.168.7.34:8082/virtual-network/96683500-b680-4d2e-9085-3622f13259e8', 'uuid': '96683500-b680-4d2e-9085-3622f13259e8'}] before deletion
2021-02-23 05:59:14,724 - WARNING - Project ctest-TestBasicVMVNx-65658814 still has VNs [{'to': ['admin_domain', 'ctest-TestBasicVMVNx-65658814', 'ctest-vn-29051427'], 'href': 'https://192.168.7.34:8082/virtual-network/96683500-b680-4d2e-9085-3622f13259e8', 'uuid': '96683500-b680-4d2e-9085-3622f13259e8'}] before deletion
2021-02-23 05:59:16,843 - WARNING - Project ctest-TestBasicVMVNx-65658814 still has VNs [{'to': ['admin_domain', 'ctest-TestBasicVMVNx-65658814', 'ctest-vn-29051427'], 'href': 'https://192.168.7.34:8082/virtual-network/96683500-b680-4d2e-9085-3622f13259e8', 'uuid': '96683500-b680-4d2e-9085-3622f13259e8'}] before deletion
2021-02-23 05:59:18,954 - WARNING - Project ctest-TestBasicVMVNx-65658814 still has VNs [{'to': ['admin_domain', 'ctest-TestBasicVMVNx-65658814', 'ctest-vn-29051427'], 'href': 'https://192.168.7.34:8082/virtual-network/96683500-b680-4d2e-9085-3622f13259e8', 'uuid': '96683500-b680-4d2e-9085-3622f13259e8'}] before deletion
2021-02-23 05:59:21,058 - WARNING - Project ctest-TestBasicVMVNx-65658814 still has VNs [{'to': ['admin_domain', 'ctest-TestBasicVMVNx-65658814', 'ctest-vn-29051427'], 'href': 'https://192.168.7.34:8082/virtual-network/96683500-b680-4d2e-9085-3622f13259e8', 'uuid': '96683500-b680-4d2e-9085-3622f13259e8'}] before deletion
2021-02-23 05:59:23,186 - WARNING - Project ctest-TestBasicVMVNx-65658814 still has VNs [{'to': ['admin_domain', 'ctest-TestBasicVMVNx-65658814', 'ctest-vn-29051427'], 'href': 'https://192.168.7.34:8082/virtual-network/96683500-b680-4d2e-9085-3622f13259e8', 'uuid': '96683500-b680-4d2e-9085-3622f13259e8'}] before deletion
2021-02-23 05:59:25,304 - WARNING - Project ctest-TestBasicVMVNx-65658814 still has VNs [{'to': ['admin_domain', 'ctest-TestBasicVMVNx-65658814', 'ctest-vn-29051427'], 'href': 'https://192.168.7.34:8082/virtual-network/96683500-b680-4d2e-9085-3622f13259e8', 'uuid': '96683500-b680-4d2e-9085-3622f13259e8'}] before deletion
2021-02-23 05:59:27,404 - WARNING - Project ctest-TestBasicVMVNx-65658814 still has VNs [{'to': ['admin_domain', 'ctest-TestBasicVMVNx-65658814', 'ctest-vn-29051427'], 'href': 'https://192.168.7.34:8082/virtual-network/96683500-b680-4d2e-9085-3622f13259e8', 'uuid': '96683500-b680-4d2e-9085-3622f13259e8'}] before deletion
2021-02-23 05:59:29,517 - WARNING - Project ctest-TestBasicVMVNx-65658814 still has VNs [{'to': ['admin_domain', 'ctest-TestBasicVMVNx-65658814', 'ctest-vn-29051427'], 'href': 'https://192.168.7.34:8082/virtual-network/96683500-b680-4d2e-9085-3622f13259e8', 'uuid': '96683500-b680-4d2e-9085-3622f13259e8'}] before deletion
2021-02-23 05:59:29,517 - WARNING - One or more references still present, will not delete the project ctest-TestBasicVMVNx-65658814
2021-02-24 06:27:18,562 - INFO - Reading existing Domain with UUID f27c063f-c6c4-434f-a616-97e72e0043e5
2021-02-24 06:27:18,589 - INFO - Using existing domain ['admin_domain'](f27c063f-c6c4-434f-a616-97e72e0043e5)
2021-02-24 06:27:18,960 - INFO - Project ctest-TestBasicVMVNx-40388268 not found, creating it
2021-02-24 06:27:19,569 - INFO - Created Project:ctest-TestBasicVMVNx-40388268, ID : 0b8de362-bd50-49d2-90e3-806703a5e7b6 
2021-02-24 06:27:23,464 - INFO - ================================================================================
2021-02-24 06:27:23,465 - INFO - STARTING TEST    : test_vm_file_trf_scp_tests
2021-02-24 06:27:23,465 - INFO - TEST DESCRIPTION : 
        Description: Test to validate File Transfer using scp between VMs. Files of different sizes.
        Test steps:
                1. Creating vm's - vm1 and vm2 and a Vn - vn222
                2. Transfer file from vm1 to vm2 with diferrent file sizes using scp
                3. file sizes - 64,1202,2210,10000
                4. verify files present in vm2 match with the size of the file sent.
        Pass criteria: File in vm2 should match with the transferred file size from vm1

        Maintainer : ganeshahv@juniper.net
        
2021-02-24 06:27:25,485 - DEBUG - Nothing to compare xmpp stats {'192.168.7.19': {'192.168.27.20': '0', '192.168.27.34': '0'}, '192.168.7.9': {'192.168.27.20': '0', '192.168.27.34': '0'}} with
2021-02-24 06:27:25,485 - INFO - Initial checks done. Running the testcase now
2021-02-24 06:27:25,485 - INFO - 
2021-02-24 06:27:27,345 - DEBUG - Response for create_network : {'network': {'status': 'ACTIVE', 'router:external': False, 'subnets': [], 'fq_name': ['admin_domain', 'ctest-TestBasicVMVNx-40388268', 'ctest-vn-80329247'], 'name': 'ctest-vn-80329247', 'admin_state_up': True, 'tenant_id': '0b8de362bd5049d290e3806703a5e7b6', 'created_at': None, 'updated_at': None, 'shared': False, 'port_security_enabled': True, 'project_id': '0b8de362bd5049d290e3806703a5e7b6', 'id': 'b257fb08-e4d1-4276-b0d5-8b75fc184ae2', 'description': ''}}
2021-02-24 06:27:27,785 - DEBUG - Response for create_subnet : {'subnet': {'name': '', 'enable_dhcp': True, 'network_id': 'b257fb08-e4d1-4276-b0d5-8b75fc184ae2', 'tenant_id': '0b8de362bd5049d290e3806703a5e7b6', 'created_at': '2021-02-24T06:27:29.197442', 'dns_nameservers': [], 'updated_at': '2021-02-24T06:27:29.197442', 'ipv6_ra_mode': None, 'allocation_pools': [{'start': '128.110.3.194', 'end': '128.110.3.254'}], 'gateway_ip': '128.110.3.193', 'dns_server_address': '128.110.3.194', 'ipv6_address_mode': None, 'ip_version': 4, 'host_routes': [], 'cidr': '128.110.3.192/26', 'id': '6b1b5778-9c86-4173-bfa6-9f9e9b4d9e74'}}
2021-02-24 06:27:27,836 - INFO - Created VN ctest-vn-80329247
2021-02-24 06:27:27,866 - DEBUG - VN ctest-vn-80329247 UUID is b257fb08-e4d1-4276-b0d5-8b75fc184ae2
2021-02-24 06:27:28,625 - DEBUG - Services list from nova: [<Service: 1>, <Service: 3>, <Service: 4>, <Service: 16>]
2021-02-24 06:27:30,449 - INFO - VM ([<Server: ctest-TestBasicVMVNx-40388268-34055092>]) created on node: (nodec9), Zone: (nova:nodec9)
2021-02-24 06:27:31,949 - INFO - VM ([<Server: ctest-TestBasicVMVNx-40388268-52698285>]) created on node: (nodec9), Zone: (nova:nodec9)
2021-02-24 06:27:31,949 - INFO - Waiting for VM ctest-TestBasicVMVNx-40388268-34055092 to be up..
2021-02-24 06:27:32,032 - DEBUG - VM <Server: ctest-TestBasicVMVNx-40388268-34055092> is still in BUILD state, Expected: ACTIVE
2021-02-24 06:27:37,226 - DEBUG - VM <Server: ctest-TestBasicVMVNx-40388268-34055092> is still in BUILD state, Expected: ACTIVE
2021-02-24 06:27:42,763 - DEBUG - VM <Server: ctest-TestBasicVMVNx-40388268-34055092> is in ACTIVE state now
2021-02-24 06:27:42,763 - INFO - VM name : ctest-TestBasicVMVNx-40388268-34055092
2021-02-24 06:27:42,965 - DEBUG - VM ctest-TestBasicVMVNx-40388268-34055092 ID is 25476c33-6534-494e-b754-e4a9de086826
2021-02-24 06:27:42,998 - DEBUG - VM ctest-TestBasicVMVNx-40388268-34055092 launched on Node nodec9.maas
2021-02-24 06:27:43,186 - DEBUG - Requesting: https://192.168.7.34:8082/virtual-machine/25476c33-6534-494e-b754-e4a9de086826
2021-02-24 06:27:43,892 - DEBUG - Requesting: https://192.168.7.34:8082/virtual-machine/25476c33-6534-494e-b754-e4a9de086826
2021-02-24 06:27:43,978 - DEBUG - Requesting: https://192.168.7.34:8082/virtual-machine-interface/ad4ecc0d-15c0-4260-835e-c8e7ab44d92d
2021-02-24 06:27:47,297 - DEBUG - (True, 'PING 169.254.0.3 (169.254.0.3) 56(84) bytes of data.\r\n\r\n--- 169.254.0.3 ping statistics ---\r\n2 packets transmitted, 0 received, 100% packet loss, time 1027ms')
2021-02-24 06:27:47,298 - DEBUG - Ping to Metadata IP 169.254.0.3 of VM ctest-TestBasicVMVNx-40388268-34055092 failed!
2021-02-24 06:27:47,336 - DEBUG - Gateway for vn admin_domain:ctest-TestBasicVMVNx-40388268:ctest-vn-80329247 is 128.110.3.193 and allocation pool is NOT set
2021-02-24 06:27:51,424 - DEBUG - (True, 'PING 169.254.0.3 (169.254.0.3) 56(84) bytes of data.\r\n\r\n--- 169.254.0.3 ping statistics ---\r\n2 packets transmitted, 0 received, 100% packet loss, time 1014ms')
2021-02-24 06:27:51,424 - DEBUG - Ping to Metadata IP 169.254.0.3 of VM ctest-TestBasicVMVNx-40388268-34055092 failed!
2021-02-24 06:27:51,457 - DEBUG - Gateway for vn admin_domain:ctest-TestBasicVMVNx-40388268:ctest-vn-80329247 is 128.110.3.193 and allocation pool is NOT set
2021-02-24 06:27:55,554 - DEBUG - (True, 'PING 169.254.0.3 (169.254.0.3) 56(84) bytes of data.\r\n\r\n--- 169.254.0.3 ping statistics ---\r\n2 packets transmitted, 0 received, 100% packet loss, time 1027ms')
2021-02-24 06:27:55,554 - DEBUG - Ping to Metadata IP 169.254.0.3 of VM ctest-TestBasicVMVNx-40388268-34055092 failed!
2021-02-24 06:27:55,589 - DEBUG - Gateway for vn admin_domain:ctest-TestBasicVMVNx-40388268:ctest-vn-80329247 is 128.110.3.193 and allocation pool is NOT set
2021-02-24 06:27:59,684 - DEBUG - (True, 'PING 169.254.0.3 (169.254.0.3) 56(84) bytes of data.\r\n\r\n--- 169.254.0.3 ping statistics ---\r\n2 packets transmitted, 0 received, 100% packet loss, time 1024ms')
2021-02-24 06:27:59,684 - DEBUG - Ping to Metadata IP 169.254.0.3 of VM ctest-TestBasicVMVNx-40388268-34055092 failed!
2021-02-24 06:27:59,718 - DEBUG - Gateway for vn admin_domain:ctest-TestBasicVMVNx-40388268:ctest-vn-80329247 is 128.110.3.193 and allocation pool is NOT set
2021-02-24 06:28:03,809 - DEBUG - (True, 'PING 169.254.0.3 (169.254.0.3) 56(84) bytes of data.\r\n\r\n--- 169.254.0.3 ping statistics ---\r\n2 packets transmitted, 0 received, 100% packet loss, time 1015ms')
2021-02-24 06:28:03,809 - DEBUG - Ping to Metadata IP 169.254.0.3 of VM ctest-TestBasicVMVNx-40388268-34055092 failed!
2021-02-24 06:28:03,844 - DEBUG - Gateway for vn admin_domain:ctest-TestBasicVMVNx-40388268:ctest-vn-80329247 is 128.110.3.193 and allocation pool is NOT set
2021-02-24 06:28:07,940 - DEBUG - (True, 'PING 169.254.0.3 (169.254.0.3) 56(84) bytes of data.\r\n\r\n--- 169.254.0.3 ping statistics ---\r\n2 packets transmitted, 0 received, 100% packet loss, time 1020ms')
2021-02-24 06:28:07,941 - DEBUG - Ping to Metadata IP 169.254.0.3 of VM ctest-TestBasicVMVNx-40388268-34055092 failed!
2021-02-24 06:28:07,973 - DEBUG - Gateway for vn admin_domain:ctest-TestBasicVMVNx-40388268:ctest-vn-80329247 is 128.110.3.193 and allocation pool is NOT set
2021-02-24 06:28:12,065 - DEBUG - (True, 'PING 169.254.0.3 (169.254.0.3) 56(84) bytes of data.\r\n\r\n--- 169.254.0.3 ping statistics ---\r\n2 packets transmitted, 0 received, 100% packet loss, time 1015ms')
2021-02-24 06:28:12,065 - DEBUG - Ping to Metadata IP 169.254.0.3 of VM ctest-TestBasicVMVNx-40388268-34055092 failed!
2021-02-24 06:28:12,103 - DEBUG - Gateway for vn admin_domain:ctest-TestBasicVMVNx-40388268:ctest-vn-80329247 is 128.110.3.193 and allocation pool is NOT set
2021-02-24 06:28:16,191 - DEBUG - (True, 'PING 169.254.0.3 (169.254.0.3) 56(84) bytes of data.\r\n\r\n--- 169.254.0.3 ping statistics ---\r\n2 packets transmitted, 0 received, 100% packet loss, time 1018ms')
2021-02-24 06:28:16,192 - DEBUG - Ping to Metadata IP 169.254.0.3 of VM ctest-TestBasicVMVNx-40388268-34055092 failed!
2021-02-24 06:28:16,225 - DEBUG - Gateway for vn admin_domain:ctest-TestBasicVMVNx-40388268:ctest-vn-80329247 is 128.110.3.193 and allocation pool is NOT set
2021-02-24 06:28:20,325 - DEBUG - (True, 'PING 169.254.0.3 (169.254.0.3) 56(84) bytes of data.\r\n\r\n--- 169.254.0.3 ping statistics ---\r\n2 packets transmitted, 0 received, 100% packet loss, time 1024ms')
2021-02-24 06:28:20,325 - DEBUG - Ping to Metadata IP 169.254.0.3 of VM ctest-TestBasicVMVNx-40388268-34055092 failed!
2021-02-24 06:28:20,362 - DEBUG - Gateway for vn admin_domain:ctest-TestBasicVMVNx-40388268:ctest-vn-80329247 is 128.110.3.193 and allocation pool is NOT set
2021-02-24 06:28:24,453 - DEBUG - (True, 'PING 169.254.0.3 (169.254.0.3) 56(84) bytes of data.\r\n\r\n--- 169.254.0.3 ping statistics ---\r\n2 packets transmitted, 0 received, 100% packet loss, time 1018ms')
2021-02-24 06:28:24,453 - DEBUG - Ping to Metadata IP 169.254.0.3 of VM ctest-TestBasicVMVNx-40388268-34055092 failed!
2021-02-24 06:28:24,490 - DEBUG - Gateway for vn admin_domain:ctest-TestBasicVMVNx-40388268:ctest-vn-80329247 is 128.110.3.193 and allocation pool is NOT set
2021-02-24 06:28:28,582 - DEBUG - (True, 'PING 169.254.0.3 (169.254.0.3) 56(84) bytes of data.\r\n\r\n--- 169.254.0.3 ping statistics ---\r\n2 packets transmitted, 0 received, 100% packet loss, time 1018ms')
2021-02-24 06:28:28,582 - DEBUG - Ping to Metadata IP 169.254.0.3 of VM ctest-TestBasicVMVNx-40388268-34055092 failed!
2021-02-24 06:28:28,614 - DEBUG - Gateway for vn admin_domain:ctest-TestBasicVMVNx-40388268:ctest-vn-80329247 is 128.110.3.193 and allocation pool is NOT set
2021-02-24 06:28:32,704 - DEBUG - (True, 'PING 169.254.0.3 (169.254.0.3) 56(84) bytes of data.\r\n\r\n--- 169.254.0.3 ping statistics ---\r\n2 packets transmitted, 0 received, 100% packet loss, time 1020ms')
2021-02-24 06:28:32,704 - DEBUG - Ping to Metadata IP 169.254.0.3 of VM ctest-TestBasicVMVNx-40388268-34055092 failed!
2021-02-24 06:28:32,736 - DEBUG - Gateway for vn admin_domain:ctest-TestBasicVMVNx-40388268:ctest-vn-80329247 is 128.110.3.193 and allocation pool is NOT set
2021-02-24 06:28:36,831 - DEBUG - (True, 'PING 169.254.0.3 (169.254.0.3) 56(84) bytes of data.\r\n\r\n--- 169.254.0.3 ping statistics ---\r\n2 packets transmitted, 0 received, 100% packet loss, time 1025ms')
2021-02-24 06:28:36,831 - DEBUG - Ping to Metadata IP 169.254.0.3 of VM ctest-TestBasicVMVNx-40388268-34055092 failed!
2021-02-24 06:28:36,861 - DEBUG - Gateway for vn admin_domain:ctest-TestBasicVMVNx-40388268:ctest-vn-80329247 is 128.110.3.193 and allocation pool is NOT set
2021-02-24 06:28:40,965 - DEBUG - (True, 'PING 169.254.0.3 (169.254.0.3) 56(84) bytes of data.\r\n\r\n--- 169.254.0.3 ping statistics ---\r\n2 packets transmitted, 0 received, 100% packet loss, time 1029ms')
2021-02-24 06:28:40,966 - DEBUG - Ping to Metadata IP 169.254.0.3 of VM ctest-TestBasicVMVNx-40388268-34055092 failed!
2021-02-24 06:28:41,006 - DEBUG - Gateway for vn admin_domain:ctest-TestBasicVMVNx-40388268:ctest-vn-80329247 is 128.110.3.193 and allocation pool is NOT set
2021-02-24 06:28:45,095 - DEBUG - (True, 'PING 169.254.0.3 (169.254.0.3) 56(84) bytes of data.\r\n\r\n--- 169.254.0.3 ping statistics ---\r\n2 packets transmitted, 0 received, 100% packet loss, time 1011ms')
2021-02-24 06:28:45,095 - DEBUG - Ping to Metadata IP 169.254.0.3 of VM ctest-TestBasicVMVNx-40388268-34055092 failed!
2021-02-24 06:28:45,133 - DEBUG - Gateway for vn admin_domain:ctest-TestBasicVMVNx-40388268:ctest-vn-80329247 is 128.110.3.193 and allocation pool is NOT set
2021-02-24 06:28:47,208 - DEBUG - (True, 'PING 169.254.0.3 (169.254.0.3) 56(84) bytes of data.\r\n64 bytes from 169.254.0.3: icmp_seq=1 ttl=63 time=4.56 ms\r\n64 bytes from 169.254.0.3: icmp_seq=2 ttl=63 time=0.743 ms\r\n\r\n--- 169.254.0.3 ping statistics ---\r\n2 packets transmitted, 2 received, 0% packet loss, time 1001ms\r\nrtt min/avg/max/mdev = 0.743/2.652/4.561/1.909 ms')
2021-02-24 06:28:47,208 - INFO - Ping to Metadata IP 169.254.0.3 of VM ctest-TestBasicVMVNx-40388268-34055092 passed
2021-02-24 06:28:47,274 - DEBUG - verify_vm_launched is skipped since self.vm_launch_flag is set
2021-02-24 06:28:47,275 - DEBUG - Waiting to SSH to VM ctest-TestBasicVMVNx-40388268-34055092, IP 128.110.3.195, Port 22
2021-02-24 06:28:47,342 - DEBUG - Error on ssh to ubuntu@169.254.0.3:22, result: /bin/bash: connect: Connection refused
/bin/bash: /dev/tcp/169.254.0.3/22: Connection refused {'failed': True, 'command': '(echo > /dev/tcp/169.254.0.3/22)', 'real_command': '/bin/bash -l -c "(echo > /dev/tcp/169.254.0.3/22)"', 'return_code': 1, 'succeeded': False, 'stderr': ''}
2021-02-24 06:28:47,558 - DEBUG - VM ctest-TestBasicVMVNx-40388268-34055092 is NOT ready for SSH connections, VM status: ACTIVE
2021-02-24 06:28:52,559 - DEBUG - verify_vm_launched is skipped since self.vm_launch_flag is set
2021-02-24 06:28:52,560 - DEBUG - Waiting to SSH to VM ctest-TestBasicVMVNx-40388268-34055092, IP 128.110.3.195, Port 22
2021-02-24 06:28:52,631 - DEBUG - Error on ssh to ubuntu@169.254.0.3:22, result: /bin/bash: connect: Connection refused
/bin/bash: /dev/tcp/169.254.0.3/22: Connection refused {'failed': True, 'command': '(echo > /dev/tcp/169.254.0.3/22)', 'real_command': '/bin/bash -l -c "(echo > /dev/tcp/169.254.0.3/22)"', 'return_code': 1, 'succeeded': False, 'stderr': ''}
2021-02-24 06:28:52,826 - DEBUG - VM ctest-TestBasicVMVNx-40388268-34055092 is NOT ready for SSH connections, VM status: ACTIVE
2021-02-24 06:28:57,827 - DEBUG - verify_vm_launched is skipped since self.vm_launch_flag is set
2021-02-24 06:28:57,827 - DEBUG - Waiting to SSH to VM ctest-TestBasicVMVNx-40388268-34055092, IP 128.110.3.195, Port 22
2021-02-24 06:28:57,894 - DEBUG - Error on ssh to ubuntu@169.254.0.3:22, result: /bin/bash: connect: Connection refused
/bin/bash: /dev/tcp/169.254.0.3/22: Connection refused {'failed': True, 'command': '(echo > /dev/tcp/169.254.0.3/22)', 'real_command': '/bin/bash -l -c "(echo > /dev/tcp/169.254.0.3/22)"', 'return_code': 1, 'succeeded': False, 'stderr': ''}
2021-02-24 06:28:58,100 - DEBUG - VM ctest-TestBasicVMVNx-40388268-34055092 is NOT ready for SSH connections, VM status: ACTIVE
2021-02-24 06:29:03,101 - DEBUG - verify_vm_launched is skipped since self.vm_launch_flag is set
2021-02-24 06:29:03,102 - DEBUG - Waiting to SSH to VM ctest-TestBasicVMVNx-40388268-34055092, IP 128.110.3.195, Port 22
2021-02-24 06:29:03,175 - DEBUG - Error on ssh to ubuntu@169.254.0.3:22, result: /bin/bash: connect: Connection refused
/bin/bash: /dev/tcp/169.254.0.3/22: Connection refused {'failed': True, 'command': '(echo > /dev/tcp/169.254.0.3/22)', 'real_command': '/bin/bash -l -c "(echo > /dev/tcp/169.254.0.3/22)"', 'return_code': 1, 'succeeded': False, 'stderr': ''}
2021-02-24 06:29:03,387 - DEBUG - VM ctest-TestBasicVMVNx-40388268-34055092 is NOT ready for SSH connections, VM status: ACTIVE
2021-02-24 06:29:08,388 - DEBUG - verify_vm_launched is skipped since self.vm_launch_flag is set
2021-02-24 06:29:08,388 - DEBUG - Waiting to SSH to VM ctest-TestBasicVMVNx-40388268-34055092, IP 128.110.3.195, Port 22
2021-02-24 06:29:08,459 - DEBUG - Error on ssh to ubuntu@169.254.0.3:22, result: /bin/bash: connect: Connection refused
/bin/bash: /dev/tcp/169.254.0.3/22: Connection refused {'failed': True, 'command': '(echo > /dev/tcp/169.254.0.3/22)', 'real_command': '/bin/bash -l -c "(echo > /dev/tcp/169.254.0.3/22)"', 'return_code': 1, 'succeeded': False, 'stderr': ''}
2021-02-24 06:29:08,667 - DEBUG - VM ctest-TestBasicVMVNx-40388268-34055092 is NOT ready for SSH connections, VM status: ACTIVE
2021-02-24 06:29:13,669 - DEBUG - verify_vm_launched is skipped since self.vm_launch_flag is set
2021-02-24 06:29:13,669 - DEBUG - Waiting to SSH to VM ctest-TestBasicVMVNx-40388268-34055092, IP 128.110.3.195, Port 22
2021-02-24 06:29:13,738 - DEBUG - Error on ssh to ubuntu@169.254.0.3:22, result: /bin/bash: connect: Connection refused
/bin/bash: /dev/tcp/169.254.0.3/22: Connection refused {'failed': True, 'command': '(echo > /dev/tcp/169.254.0.3/22)', 'real_command': '/bin/bash -l -c "(echo > /dev/tcp/169.254.0.3/22)"', 'return_code': 1, 'succeeded': False, 'stderr': ''}
2021-02-24 06:29:13,942 - DEBUG - VM ctest-TestBasicVMVNx-40388268-34055092 is NOT ready for SSH connections, VM status: ACTIVE
2021-02-24 06:29:18,943 - DEBUG - verify_vm_launched is skipped since self.vm_launch_flag is set
2021-02-24 06:29:18,943 - DEBUG - Waiting to SSH to VM ctest-TestBasicVMVNx-40388268-34055092, IP 128.110.3.195, Port 22
2021-02-24 06:29:19,012 - DEBUG - Error on ssh to ubuntu@169.254.0.3:22, result: /bin/bash: connect: Connection refused
/bin/bash: /dev/tcp/169.254.0.3/22: Connection refused {'failed': True, 'command': '(echo > /dev/tcp/169.254.0.3/22)', 'real_command': '/bin/bash -l -c "(echo > /dev/tcp/169.254.0.3/22)"', 'return_code': 1, 'succeeded': False, 'stderr': ''}
2021-02-24 06:29:19,307 - DEBUG - VM ctest-TestBasicVMVNx-40388268-34055092 is NOT ready for SSH connections, VM status: ACTIVE
2021-02-24 06:29:24,308 - DEBUG - verify_vm_launched is skipped since self.vm_launch_flag is set
2021-02-24 06:29:24,309 - DEBUG - Waiting to SSH to VM ctest-TestBasicVMVNx-40388268-34055092, IP 128.110.3.195, Port 22
2021-02-24 06:29:24,378 - DEBUG - Error on ssh to ubuntu@169.254.0.3:22, result: /bin/bash: connect: Connection refused
/bin/bash: /dev/tcp/169.254.0.3/22: Connection refused {'failed': True, 'command': '(echo > /dev/tcp/169.254.0.3/22)', 'real_command': '/bin/bash -l -c "(echo > /dev/tcp/169.254.0.3/22)"', 'return_code': 1, 'succeeded': False, 'stderr': ''}
2021-02-24 06:29:24,578 - DEBUG - VM ctest-TestBasicVMVNx-40388268-34055092 is NOT ready for SSH connections, VM status: ACTIVE
2021-02-24 06:29:29,580 - DEBUG - verify_vm_launched is skipped since self.vm_launch_flag is set
2021-02-24 06:29:29,580 - DEBUG - Waiting to SSH to VM ctest-TestBasicVMVNx-40388268-34055092, IP 128.110.3.195, Port 22
2021-02-24 06:29:29,653 - DEBUG - Error on ssh to ubuntu@169.254.0.3:22, result: /bin/bash: connect: Connection refused
/bin/bash: /dev/tcp/169.254.0.3/22: Connection refused {'failed': True, 'command': '(echo > /dev/tcp/169.254.0.3/22)', 'real_command': '/bin/bash -l -c "(echo > /dev/tcp/169.254.0.3/22)"', 'return_code': 1, 'succeeded': False, 'stderr': ''}
2021-02-24 06:29:29,853 - DEBUG - VM ctest-TestBasicVMVNx-40388268-34055092 is NOT ready for SSH connections, VM status: ACTIVE
2021-02-24 06:29:34,853 - DEBUG - verify_vm_launched is skipped since self.vm_launch_flag is set
2021-02-24 06:29:34,854 - DEBUG - Waiting to SSH to VM ctest-TestBasicVMVNx-40388268-34055092, IP 128.110.3.195, Port 22
2021-02-24 06:29:35,030 - DEBUG - VM ctest-TestBasicVMVNx-40388268-34055092 is ready for SSH connections
2021-02-24 06:29:35,030 - INFO - Waiting for VM ctest-TestBasicVMVNx-40388268-52698285 to be up..
2021-02-24 06:29:35,265 - DEBUG - VM <Server: ctest-TestBasicVMVNx-40388268-52698285> is in ACTIVE state now
2021-02-24 06:29:35,266 - INFO - VM name : ctest-TestBasicVMVNx-40388268-52698285
2021-02-24 06:29:35,472 - DEBUG - VM ctest-TestBasicVMVNx-40388268-52698285 ID is 069f6b49-23cd-4d2d-87d1-3b49ca3549d6
2021-02-24 06:29:35,473 - DEBUG - VM ctest-TestBasicVMVNx-40388268-52698285 launched on Node nodec9.maas
2021-02-24 06:29:35,667 - DEBUG - Requesting: https://192.168.7.34:8082/virtual-machine/069f6b49-23cd-4d2d-87d1-3b49ca3549d6
2021-02-24 06:29:35,695 - DEBUG - Requesting: https://192.168.7.34:8082/virtual-machine-interface/776a2267-46f9-4704-97b5-ac4f1f4d7a81
2021-02-24 06:29:36,904 - DEBUG - (True, 'PING 169.254.0.5 (169.254.0.5) 56(84) bytes of data.\r\n64 bytes from 169.254.0.5: icmp_seq=1 ttl=63 time=6.82 ms\r\n64 bytes from 169.254.0.5: icmp_seq=2 ttl=63 time=3.03 ms\r\n\r\n--- 169.254.0.5 ping statistics ---\r\n2 packets transmitted, 2 received, 0% packet loss, time 1001ms\r\nrtt min/avg/max/mdev = 3.035/4.928/6.822/1.894 ms')
2021-02-24 06:29:36,904 - INFO - Ping to Metadata IP 169.254.0.5 of VM ctest-TestBasicVMVNx-40388268-52698285 passed
2021-02-24 06:29:36,961 - DEBUG - verify_vm_launched is skipped since self.vm_launch_flag is set
2021-02-24 06:29:36,962 - DEBUG - Waiting to SSH to VM ctest-TestBasicVMVNx-40388268-52698285, IP 128.110.3.196, Port 22
2021-02-24 06:29:37,138 - DEBUG - VM ctest-TestBasicVMVNx-40388268-52698285 is ready for SSH connections
2021-02-24 06:29:37,138 - DEBUG - FILE SIZE = 1355B
2021-02-24 06:29:37,138 - DEBUG - Transferring the file from ctest-TestBasicVMVNx-40388268-34055092 to ctest-TestBasicVMVNx-40388268-52698285 using scp
2021-02-24 06:29:37,139 - DEBUG - Running remote_cmd, Cmd : dd bs=1355 count=1 if=/dev/zero of=testfile, host_string: ubuntu@169.254.0.3, password: ubuntugateway: root@192.168.7.9, gateway password: c0ntrail123
2021-02-24 06:29:37,139 - DEBUG - dd bs=1355 count=1 if=/dev/zero of=testfile
2021-02-24 06:29:53,643 - DEBUG - 1+0 records in
1+0 records out
1355 bytes (1.4 kB) copied, 0.0737362 s, 18.4 kB/s
2021-02-24 06:29:53,644 - DEBUG - Running remote_cmd, Cmd : timeout 40 scp -o StrictHostKeyChecking=no testfile ubuntu@[128.110.3.196]:, host_string: ubuntu@169.254.0.3, password: ubuntugateway: root@192.168.7.9, gateway password: c0ntrail123
2021-02-24 06:29:53,644 - DEBUG - timeout 40 scp -o StrictHostKeyChecking=no testfile ubuntu@[128.110.3.196]:
2021-02-24 06:30:00,860 - DEBUG - Warning: Permanently added '128.110.3.196' (ECDSA) to the list of known hosts.
testfile                                        0%    0     0.0KB/s   --:-- ETAtestfile                                      100% 1355     1.3KB/s   00:00
2021-02-24 06:30:00,861 - DEBUG - {'timeout 40 scp -o StrictHostKeyChecking=no testfile ubuntu@[128.110.3.196]:': "Warning: Permanently added '128.110.3.196' (ECDSA) to the list of known hosts.\r\r\n\rtestfile                                        0%    0     0.0KB/s   --:-- ETA\rtestfile                                      100% 1355     1.3KB/s   00:00"}
2021-02-24 06:30:00,861 - DEBUG - Running remote_cmd, Cmd : sync, host_string: ubuntu@169.254.0.3, password: ubuntugateway: root@192.168.7.9, gateway password: c0ntrail123
2021-02-24 06:30:00,862 - DEBUG - sync
2021-02-24 06:30:01,700 - DEBUG - None
2021-02-24 06:30:01,701 - DEBUG - Running remote_cmd, Cmd : wc -c testfile, host_string: ubuntu@169.254.0.5, password: ubuntugateway: root@192.168.7.9, gateway password: c0ntrail123
2021-02-24 06:30:01,701 - DEBUG - wc -c testfile
2021-02-24 06:30:05,136 - DEBUG - 1355 testfile
2021-02-24 06:30:05,136 - INFO - File of size 1355 is trasferred successfully to                         128.110.3.196 by scp 
2021-02-24 06:30:05,136 - DEBUG - FILE SIZE = 3000B
2021-02-24 06:30:05,137 - DEBUG - Transferring the file from ctest-TestBasicVMVNx-40388268-34055092 to ctest-TestBasicVMVNx-40388268-52698285 using scp
2021-02-24 06:30:05,137 - DEBUG - Running remote_cmd, Cmd : dd bs=3000 count=1 if=/dev/zero of=testfile, host_string: ubuntu@169.254.0.3, password: ubuntugateway: root@192.168.7.9, gateway password: c0ntrail123
2021-02-24 06:30:05,137 - DEBUG - dd bs=3000 count=1 if=/dev/zero of=testfile
2021-02-24 06:30:05,579 - DEBUG - 1+0 records in
1+0 records out
3000 bytes (3.0 kB) copied, 0.0146836 s, 204 kB/s
2021-02-24 06:30:05,580 - DEBUG - Running remote_cmd, Cmd : timeout 40 scp -o StrictHostKeyChecking=no testfile ubuntu@[128.110.3.196]:, host_string: ubuntu@169.254.0.3, password: ubuntugateway: root@192.168.7.9, gateway password: c0ntrail123
2021-02-24 06:30:05,580 - DEBUG - timeout 40 scp -o StrictHostKeyChecking=no testfile ubuntu@[128.110.3.196]:
2021-02-24 06:30:10,030 - DEBUG - testfile                                        0%    0     0.0KB/s   --:-- ETAtestfile                                      100% 3000     2.9KB/s   00:00
2021-02-24 06:30:10,031 - DEBUG - {'timeout 40 scp -o StrictHostKeyChecking=no testfile ubuntu@[128.110.3.196]:': 'testfile                                        0%    0     0.0KB/s   --:-- ETA\rtestfile                                      100% 3000     2.9KB/s   00:00'}
2021-02-24 06:30:10,031 - DEBUG - Running remote_cmd, Cmd : sync, host_string: ubuntu@169.254.0.3, password: ubuntugateway: root@192.168.7.9, gateway password: c0ntrail123
2021-02-24 06:30:10,031 - DEBUG - sync
2021-02-24 06:30:10,394 - DEBUG - None
2021-02-24 06:30:10,394 - DEBUG - Running remote_cmd, Cmd : wc -c testfile, host_string: ubuntu@169.254.0.5, password: ubuntugateway: root@192.168.7.9, gateway password: c0ntrail123
2021-02-24 06:30:10,394 - DEBUG - wc -c testfile
2021-02-24 06:30:10,718 - DEBUG - 3000 testfile
2021-02-24 06:30:10,718 - INFO - File of size 3000 is trasferred successfully to                         128.110.3.196 by scp 
2021-02-24 06:30:10,719 - INFO - Deleting VM ctest-TestBasicVMVNx-40388268-52698285
2021-02-24 06:30:11,838 - INFO - Deleting VM ctest-TestBasicVMVNx-40388268-34055092
2021-02-24 06:30:12,330 - INFO - Deleting VN ctest-vn-80329247 
2021-02-24 06:30:12,428 - DEBUG - VN b257fb08-e4d1-4276-b0d5-8b75fc184ae2 still in use: Unable to complete operation on network b257fb08-e4d1-4276-b0d5-8b75fc184ae2. There are one or more ports still in use on the network.
Neutron server returns request_ids: ['req-e7d0fb21-dc86-4af5-9884-08a9e34b9608']
2021-02-24 06:30:12,428 - WARNING - Deleting VN ctest-vn-80329247 failed..Will retry
2021-02-24 06:30:14,722 - DEBUG - Response for deleting network ()
2021-02-24 06:30:16,810 - DEBUG - No XMPP flaps were noticed during the test
2021-02-24 06:30:16,810 - INFO - END TEST : test_vm_file_trf_scp_tests : PASSED[0:02:53]
2021-02-24 06:30:16,811 - INFO - --------------------------------------------------------------------------------
2021-02-24 06:30:18,661 - INFO - Deleted project: ctest-TestBasicVMVNx-40388268, ID : 0b8de362-bd50-49d2-90e3-806703a5e7b6 
