2021-02-18 05:43:53,502 - INFO - Using existing project ['admin_domain', 'admin'](6d52ffce-adf6-4a1b-b907-bb9dd95efc70)
2021-02-18 05:43:53,651 - INFO - Using existing project ['admin_domain', 'admin'](6d52ffce-adf6-4a1b-b907-bb9dd95efc70)
2021-02-18 05:43:53,684 - INFO - Adding rules to the default security group in Project admin
2021-02-18 06:04:46,220 - DEBUG - Not creating keypair since it exists
2021-02-18 06:04:46,874 - INFO - Using existing project ['admin_domain', 'admin'](6d52ffce-adf6-4a1b-b907-bb9dd95efc70)
2021-02-18 06:04:46,997 - INFO - Using existing project ['admin_domain', 'admin'](6d52ffce-adf6-4a1b-b907-bb9dd95efc70)
2021-02-18 06:04:47,025 - INFO - Adding rules to the default security group in Project admin
2021-02-18 06:08:55,238 - DEBUG - Not creating keypair since it exists
2021-02-18 06:08:55,917 - INFO - Using existing project ['admin_domain', 'admin'](6d52ffce-adf6-4a1b-b907-bb9dd95efc70)
2021-02-18 06:08:56,041 - INFO - Using existing project ['admin_domain', 'admin'](6d52ffce-adf6-4a1b-b907-bb9dd95efc70)
2021-02-18 06:08:56,072 - INFO - Adding rules to the default security group in Project admin
2021-02-18 06:08:56,210 - DEBUG - Container None not in host 192.168.7.18, copying to  host itself
2021-02-18 06:09:13,265 - DEBUG - Container None not in host 192.168.7.18, copying to  host itself
2021-02-18 06:11:47,730 - DEBUG - Not creating keypair since it exists
2021-02-18 06:11:48,423 - INFO - Using existing project ['admin_domain', 'admin'](6d52ffce-adf6-4a1b-b907-bb9dd95efc70)
2021-02-18 06:11:48,559 - INFO - Using existing project ['admin_domain', 'admin'](6d52ffce-adf6-4a1b-b907-bb9dd95efc70)
2021-02-18 06:11:48,591 - INFO - Adding rules to the default security group in Project admin
2021-02-18 06:11:48,750 - DEBUG - Container None not in host 192.168.7.18, copying to  host itself
2021-02-18 06:14:21,229 - DEBUG - Not creating keypair since it exists
2021-02-18 06:14:21,772 - INFO - Using existing project ['admin_domain', 'admin'](6d52ffce-adf6-4a1b-b907-bb9dd95efc70)
2021-02-18 06:14:21,905 - INFO - Using existing project ['admin_domain', 'admin'](6d52ffce-adf6-4a1b-b907-bb9dd95efc70)
2021-02-18 06:14:21,936 - INFO - Adding rules to the default security group in Project admin
2021-02-18 06:17:25,534 - DEBUG - Container None not in host 192.168.7.18, copying to  host itself
2021-02-18 07:23:13,756 - DEBUG - Not creating keypair since it exists
2021-02-18 07:23:14,471 - INFO - Using existing project ['admin_domain', 'admin'](6d52ffce-adf6-4a1b-b907-bb9dd95efc70)
2021-02-18 07:23:14,614 - INFO - Using existing project ['admin_domain', 'admin'](6d52ffce-adf6-4a1b-b907-bb9dd95efc70)
2021-02-18 07:23:14,641 - INFO - Adding rules to the default security group in Project admin
2021-02-18 07:23:27,627 - DEBUG - Container None not in host 192.168.7.18, copying to  host itself
2021-02-18 07:25:29,017 - DEBUG - Not creating keypair since it exists
2021-02-18 07:25:29,764 - INFO - Using existing project ['admin_domain', 'admin'](6d52ffce-adf6-4a1b-b907-bb9dd95efc70)
2021-02-18 07:25:29,895 - INFO - Using existing project ['admin_domain', 'admin'](6d52ffce-adf6-4a1b-b907-bb9dd95efc70)
2021-02-18 07:25:29,925 - INFO - Adding rules to the default security group in Project admin
2021-02-18 07:25:35,064 - DEBUG - Container None not in host 192.168.7.18, copying to  host itself
2021-02-18 07:25:43,930 - DEBUG - Container None not in host 192.168.7.18, copying to  host itself
2021-02-18 07:26:25,176 - INFO - ================================================================================
2021-02-18 07:26:25,176 - INFO - STARTING TEST    : test_only_pods_and_deployments_create
2021-02-18 07:26:25,178 - INFO - TEST DESCRIPTION : 
        Description: Test to validate only userA can create pods and deployments
         Test steps:
                1. Create stackrc_dict for userA
                2. Create the resource expectation list
                3. Perform create and delete operations
         Pass criteria: userA must only be able to create pods and deployments and nothing else
         Maintainer : nuthanc@juniper.net
        
2021-02-18 07:26:26,492 - DEBUG - Skipping xmpp flap check
2021-02-18 07:26:26,492 - INFO - Initial checks done. Running the testcase now
2021-02-18 07:26:26,492 - INFO - 
2021-02-18 07:26:26,493 - DEBUG - Container None not in host 192.168.7.18, copying to  host itself
2021-02-18 07:26:28,496 - ERROR - TypeError
Python 3.6.8: /usr/bin/python3
Thu Feb 18 07:26:27 2021

A problem occurred in a Python script.  Here is the sequence of
function calls leading up to the error, in the order they occurred.

 /contrail-test/tcutils/wrappers.py in wrapper(self=<serial_scripts.k8s_auth.test_policy_combo.TestP...s_and_deployments_create[auth] id=0x7f03a3866b70>, *args=(), **kwargs={})
   80             log.info('Initial checks done. Running the testcase now')
   81             log.info('')
   82             result = function(self, *args, **kwargs)
   83             if self.inputs.upgrade:
   84                 pid = os.getpid()
result = None
function = <function TestPolicyCombo.test_only_pods_and_deployments_create>
self = <serial_scripts.k8s_auth.test_policy_combo.TestP...s_and_deployments_create[auth] id=0x7f03a3866b70>
args = ()
kwargs = {}

 /contrail-test/serial_scripts/k8s_auth/test_policy_combo.py in test_only_pods_and_deployments_create(self=<serial_scripts.k8s_auth.test_policy_combo.TestP...s_and_deployments_create[auth] id=0x7f03a3866b70>)
  107         ResourceUtil.perform_operations(
  108             stackrc_dict=stackrc_dict,
  109             resource_expectation=resource_expectation, inputs=self.inputs)
  110 
  111     @test.attr(type=['auth'])
resource_expectation = {'daemonset': False, 'deployment': True, 'ingress': False, 'namespace': False, 'network_attachment_definition': False, 'network_policy': False, 'pod': True, 'service': False}
inputs undefined
self = <serial_scripts.k8s_auth.test_policy_combo.TestP...s_and_deployments_create[auth] id=0x7f03a3866b70>
self.inputs = <common.contrail_test_init.ContrailTestInit object>

 /contrail-test/tcutils/kubernetes/auth/resource_util.py in perform_operations(stackrc_dict={'auth_url': 'http://192.168.7.14:5000/v3', 'domain_name': 'userA_domain', 'password': 'c0ntrail123', 'project_name': 'userA_project', 'user_name': 'userA'}, resource_expectation={'daemonset': False, 'deployment': True, 'ingress': False, 'namespace': False, 'network_attachment_definition': False, 'network_policy': False, 'pod': True, 'service': False}, namespace='default', inputs=<common.contrail_test_init.ContrailTestInit object>)
   97             resource_expectation=resource_expectation,
   98             namespace=namespace,
   99             stackrc_file=stackrc_file, inputs=inputs)
  100         ResourceUtil.resource_with_expectation(
  101             verb='delete',
stackrc_file = '/var/tmp/templates/stackrc.sh'
inputs = <common.contrail_test_init.ContrailTestInit object>

 /contrail-test/tcutils/kubernetes/auth/resource_util.py in resource_with_expectation(verb='create', resource_expectation={'daemonset': False, 'deployment': True, 'ingress': False, 'namespace': False, 'network_attachment_definition': False, 'network_policy': False, 'pod': True, 'service': False}, namespace='default', stackrc_file='/var/tmp/templates/stackrc.sh', inputs=<common.contrail_test_init.ContrailTestInit object>)
   70                     else:
   71                         logger.error(error)
   72                     logger.error('Error while %s %s' (resource, verb))
   73                     raise Exception(error)
   74 
global logger = <Logger auth (DEBUG)>
logger.error = <bound method Logger.error of <Logger auth (DEBUG)>>
resource = 'pod'
verb = 'create'
TypeError: 'str' object is not callable
    __cause__ = None
    __class__ = <class 'TypeError'>
    __context__ = None
    __delattr__ = <method-wrapper '__delattr__' of TypeError object>
    __dict__ = {}
    __dir__ = <built-in method __dir__ of TypeError object>
    __doc__ = 'Inappropriate argument type.'
    __eq__ = <method-wrapper '__eq__' of TypeError object>
    __format__ = <built-in method __format__ of TypeError object>
    __ge__ = <method-wrapper '__ge__' of TypeError object>
    __getattribute__ = <method-wrapper '__getattribute__' of TypeError object>
    __gt__ = <method-wrapper '__gt__' of TypeError object>
    __hash__ = <method-wrapper '__hash__' of TypeError object>
    __init__ = <method-wrapper '__init__' of TypeError object>
    __init_subclass__ = <built-in method __init_subclass__ of type object>
    __le__ = <method-wrapper '__le__' of TypeError object>
    __lt__ = <method-wrapper '__lt__' of TypeError object>
    __ne__ = <method-wrapper '__ne__' of TypeError object>
    __new__ = <built-in method __new__ of type object>
    __reduce__ = <built-in method __reduce__ of TypeError object>
    __reduce_ex__ = <built-in method __reduce_ex__ of TypeError object>
    __repr__ = <method-wrapper '__repr__' of TypeError object>
    __setattr__ = <method-wrapper '__setattr__' of TypeError object>
    __setstate__ = <built-in method __setstate__ of TypeError object>
    __sizeof__ = <built-in method __sizeof__ of TypeError object>
    __str__ = <method-wrapper '__str__' of TypeError object>
    __subclasshook__ = <built-in method __subclasshook__ of type object>
    __suppress_context__ = False
    __traceback__ = <traceback object>
    args = ("'str' object is not callable",)
    with_traceback = <built-in method with_traceback of TypeError object>

The above is a description of an error in a Python program.  Here is
the original traceback:

Traceback (most recent call last):
  File "/contrail-test/tcutils/wrappers.py", line 82, in wrapper
    result = function(self, *args, **kwargs)
  File "/contrail-test/serial_scripts/k8s_auth/test_policy_combo.py", line 109, in test_only_pods_and_deployments_create
    resource_expectation=resource_expectation, inputs=self.inputs)
  File "/contrail-test/tcutils/kubernetes/auth/resource_util.py", line 99, in perform_operations
    stackrc_file=stackrc_file, inputs=inputs)
  File "/contrail-test/tcutils/kubernetes/auth/resource_util.py", line 72, in resource_with_expectation
    logger.error('Error while %s %s' (resource, verb))
TypeError: 'str' object is not callable



2021-02-18 07:26:28,497 - DEBUG - Skipping xmpp flap check
2021-02-18 07:26:28,497 - INFO - 
2021-02-18 07:26:28,497 - INFO - END TEST : test_only_pods_and_deployments_create : FAILED[0:00:03]
2021-02-18 07:26:28,498 - INFO - --------------------------------------------------------------------------------
2021-02-18 07:26:28,506 - INFO - ================================================================================
2021-02-18 07:26:28,506 - INFO - STARTING TEST    : test_only_pods_and_deployments_delete
2021-02-18 07:26:28,507 - INFO - TEST DESCRIPTION : 
        Description: Test to validate only userB can delete pods and deployments
         Test steps:
                1. Create stackrc_dict for userB
                2. Create the resource expectation list
                3. Perform create and delete operations
         Pass criteria: userB must only be able to delete pods and deployments and nothing else
         Maintainer : nuthanc@juniper.net
        
2021-02-18 07:26:29,829 - DEBUG - Skipping xmpp flap check
2021-02-18 07:26:29,829 - INFO - Initial checks done. Running the testcase now
2021-02-18 07:26:29,829 - INFO - 
2021-02-18 07:26:29,830 - DEBUG - Container None not in host 192.168.7.18, copying to  host itself
2021-02-18 07:26:31,808 - ERROR - TypeError
Python 3.6.8: /usr/bin/python3
Thu Feb 18 07:26:30 2021

A problem occurred in a Python script.  Here is the sequence of
function calls leading up to the error, in the order they occurred.

 /contrail-test/tcutils/wrappers.py in wrapper(self=<serial_scripts.k8s_auth.test_policy_combo.TestP...s_and_deployments_delete[auth] id=0x7f03a3866cf8>, *args=(), **kwargs={})
   80             log.info('Initial checks done. Running the testcase now')
   81             log.info('')
   82             result = function(self, *args, **kwargs)
   83             if self.inputs.upgrade:
   84                 pid = os.getpid()
result = None
function = <function TestPolicyCombo.test_only_pods_and_deployments_delete>
self = <serial_scripts.k8s_auth.test_policy_combo.TestP...s_and_deployments_delete[auth] id=0x7f03a3866cf8>
args = ()
kwargs = {}

 /contrail-test/serial_scripts/k8s_auth/test_policy_combo.py in test_only_pods_and_deployments_delete(self=<serial_scripts.k8s_auth.test_policy_combo.TestP...s_and_deployments_delete[auth] id=0x7f03a3866cf8>)
  131         ResourceUtil.perform_operations(
  132             stackrc_dict=stackrc_dict,
  133             resource_expectation=resource_expectation, inputs=self.inputs)
  134 
  135     @test.attr(type=['auth'])
resource_expectation = {'daemonset': False, 'deployment': True, 'ingress': False, 'namespace': False, 'network_attachment_definition': False, 'network_policy': False, 'pod': True, 'service': False}
inputs undefined
self = <serial_scripts.k8s_auth.test_policy_combo.TestP...s_and_deployments_delete[auth] id=0x7f03a3866cf8>
self.inputs = <common.contrail_test_init.ContrailTestInit object>

 /contrail-test/tcutils/kubernetes/auth/resource_util.py in perform_operations(stackrc_dict={'auth_url': 'http://192.168.7.14:5000/v3', 'domain_name': 'userB_domain', 'password': 'c0ntrail123', 'project_name': 'userB_project', 'user_name': 'userB'}, resource_expectation={'daemonset': False, 'deployment': True, 'ingress': False, 'namespace': False, 'network_attachment_definition': False, 'network_policy': False, 'pod': True, 'service': False}, namespace='default', inputs=<common.contrail_test_init.ContrailTestInit object>)
   97             resource_expectation=resource_expectation,
   98             namespace=namespace,
   99             stackrc_file=stackrc_file, inputs=inputs)
  100         ResourceUtil.resource_with_expectation(
  101             verb='delete',
stackrc_file = '/var/tmp/templates/stackrc.sh'
inputs = <common.contrail_test_init.ContrailTestInit object>

 /contrail-test/tcutils/kubernetes/auth/resource_util.py in resource_with_expectation(verb='create', resource_expectation={'daemonset': False, 'deployment': True, 'ingress': False, 'namespace': False, 'network_attachment_definition': False, 'network_policy': False, 'pod': True, 'service': False}, namespace='default', stackrc_file='/var/tmp/templates/stackrc.sh', inputs=<common.contrail_test_init.ContrailTestInit object>)
   70                     else:
   71                         logger.error(error)
   72                     logger.error('Error while %s %s' (resource, verb))
   73                     raise Exception(error)
   74 
global logger = <Logger auth (DEBUG)>
logger.error = <bound method Logger.error of <Logger auth (DEBUG)>>
resource = 'pod'
verb = 'create'
TypeError: 'str' object is not callable
    __cause__ = None
    __class__ = <class 'TypeError'>
    __context__ = None
    __delattr__ = <method-wrapper '__delattr__' of TypeError object>
    __dict__ = {}
    __dir__ = <built-in method __dir__ of TypeError object>
    __doc__ = 'Inappropriate argument type.'
    __eq__ = <method-wrapper '__eq__' of TypeError object>
    __format__ = <built-in method __format__ of TypeError object>
    __ge__ = <method-wrapper '__ge__' of TypeError object>
    __getattribute__ = <method-wrapper '__getattribute__' of TypeError object>
    __gt__ = <method-wrapper '__gt__' of TypeError object>
    __hash__ = <method-wrapper '__hash__' of TypeError object>
    __init__ = <method-wrapper '__init__' of TypeError object>
    __init_subclass__ = <built-in method __init_subclass__ of type object>
    __le__ = <method-wrapper '__le__' of TypeError object>
    __lt__ = <method-wrapper '__lt__' of TypeError object>
    __ne__ = <method-wrapper '__ne__' of TypeError object>
    __new__ = <built-in method __new__ of type object>
    __reduce__ = <built-in method __reduce__ of TypeError object>
    __reduce_ex__ = <built-in method __reduce_ex__ of TypeError object>
    __repr__ = <method-wrapper '__repr__' of TypeError object>
    __setattr__ = <method-wrapper '__setattr__' of TypeError object>
    __setstate__ = <built-in method __setstate__ of TypeError object>
    __sizeof__ = <built-in method __sizeof__ of TypeError object>
    __str__ = <method-wrapper '__str__' of TypeError object>
    __subclasshook__ = <built-in method __subclasshook__ of type object>
    __suppress_context__ = False
    __traceback__ = <traceback object>
    args = ("'str' object is not callable",)
    with_traceback = <built-in method with_traceback of TypeError object>

The above is a description of an error in a Python program.  Here is
the original traceback:

Traceback (most recent call last):
  File "/contrail-test/tcutils/wrappers.py", line 82, in wrapper
    result = function(self, *args, **kwargs)
  File "/contrail-test/serial_scripts/k8s_auth/test_policy_combo.py", line 133, in test_only_pods_and_deployments_delete
    resource_expectation=resource_expectation, inputs=self.inputs)
  File "/contrail-test/tcutils/kubernetes/auth/resource_util.py", line 99, in perform_operations
    stackrc_file=stackrc_file, inputs=inputs)
  File "/contrail-test/tcutils/kubernetes/auth/resource_util.py", line 72, in resource_with_expectation
    logger.error('Error while %s %s' (resource, verb))
TypeError: 'str' object is not callable



2021-02-18 07:26:31,808 - DEBUG - Skipping xmpp flap check
2021-02-18 07:26:31,808 - INFO - 
2021-02-18 07:26:31,809 - INFO - END TEST : test_only_pods_and_deployments_delete : FAILED[0:00:03]
2021-02-18 07:26:31,809 - INFO - --------------------------------------------------------------------------------
2021-02-18 07:26:31,815 - INFO - ================================================================================
2021-02-18 07:26:31,816 - INFO - STARTING TEST    : test_only_pods_deployments_services_in_easy_ns
2021-02-18 07:26:31,816 - INFO - TEST DESCRIPTION : 
        For userD user, any operation on pods, deployments and services but only in easy namespace
        Description: Test to validate only userD can perform any operation on pods, deployments and services but only in easy namespace
         Test steps:
                1. Create stackrc_dict for userD
                2. Create the resource expectation list
                3. Perform create and delete operations in default namespace and easy_ns namespace
         Pass criteria: userD must only be able to perform any operation on pods, deployments and services in easy namespace and nothing else
         Maintainer : nuthanc@juniper.net
        
2021-02-18 07:26:33,120 - DEBUG - Skipping xmpp flap check
2021-02-18 07:26:33,121 - INFO - Initial checks done. Running the testcase now
2021-02-18 07:26:33,121 - INFO - 
2021-02-18 07:26:33,122 - DEBUG - Container None not in host 192.168.7.18, copying to  host itself
2021-02-18 07:26:35,068 - ERROR - TypeError
Python 3.6.8: /usr/bin/python3
Thu Feb 18 07:26:33 2021

A problem occurred in a Python script.  Here is the sequence of
function calls leading up to the error, in the order they occurred.

 /contrail-test/tcutils/wrappers.py in wrapper(self=<serial_scripts.k8s_auth.test_policy_combo.TestP...ents_services_in_easy_ns[auth] id=0x7f03a386c160>, *args=(), **kwargs={})
   80             log.info('Initial checks done. Running the testcase now')
   81             log.info('')
   82             result = function(self, *args, **kwargs)
   83             if self.inputs.upgrade:
   84                 pid = os.getpid()
result = None
function = <function TestPolicyCombo.test_only_pods_deployments_services_in_easy_ns>
self = <serial_scripts.k8s_auth.test_policy_combo.TestP...ents_services_in_easy_ns[auth] id=0x7f03a386c160>
args = ()
kwargs = {}

 /contrail-test/serial_scripts/k8s_auth/test_policy_combo.py in test_only_pods_deployments_services_in_easy_ns(self=<serial_scripts.k8s_auth.test_policy_combo.TestP...ents_services_in_easy_ns[auth] id=0x7f03a386c160>)
  188         ResourceUtil.perform_operations(
  189             resource_expectation=resource_expectation,
  190             stackrc_dict=stackrc_dict, inputs=self.inputs)
  191         ResourceUtil.perform_operations(
  192             stackrc_dict=stackrc_dict,
stackrc_dict = {'auth_url': 'http://192.168.7.14:5000/v3', 'domain_name': 'userD_domain', 'password': 'c0ntrail123', 'project_name': 'userD_project', 'user_name': 'userD'}
inputs undefined
self = <serial_scripts.k8s_auth.test_policy_combo.TestP...ents_services_in_easy_ns[auth] id=0x7f03a386c160>
self.inputs = <common.contrail_test_init.ContrailTestInit object>

 /contrail-test/tcutils/kubernetes/auth/resource_util.py in perform_operations(stackrc_dict={'auth_url': 'http://192.168.7.14:5000/v3', 'domain_name': 'userD_domain', 'password': 'c0ntrail123', 'project_name': 'userD_project', 'user_name': 'userD'}, resource_expectation={'daemonset': False, 'deployment': True, 'ingress': False, 'namespace': True, 'network_attachment_definition': False, 'network_policy': False, 'pod': True, 'service': True}, namespace='default', inputs=<common.contrail_test_init.ContrailTestInit object>)
   97             resource_expectation=resource_expectation,
   98             namespace=namespace,
   99             stackrc_file=stackrc_file, inputs=inputs)
  100         ResourceUtil.resource_with_expectation(
  101             verb='delete',
stackrc_file = '/var/tmp/templates/stackrc.sh'
inputs = <common.contrail_test_init.ContrailTestInit object>

 /contrail-test/tcutils/kubernetes/auth/resource_util.py in resource_with_expectation(verb='create', resource_expectation={'daemonset': False, 'deployment': True, 'ingress': False, 'namespace': True, 'network_attachment_definition': False, 'network_policy': False, 'pod': True, 'service': True}, namespace='default', stackrc_file='/var/tmp/templates/stackrc.sh', inputs=<common.contrail_test_init.ContrailTestInit object>)
   70                     else:
   71                         logger.error(error)
   72                     logger.error('Error while %s %s' (resource, verb))
   73                     raise Exception(error)
   74 
global logger = <Logger auth (DEBUG)>
logger.error = <bound method Logger.error of <Logger auth (DEBUG)>>
resource = 'pod'
verb = 'create'
TypeError: 'str' object is not callable
    __cause__ = None
    __class__ = <class 'TypeError'>
    __context__ = None
    __delattr__ = <method-wrapper '__delattr__' of TypeError object>
    __dict__ = {}
    __dir__ = <built-in method __dir__ of TypeError object>
    __doc__ = 'Inappropriate argument type.'
    __eq__ = <method-wrapper '__eq__' of TypeError object>
    __format__ = <built-in method __format__ of TypeError object>
    __ge__ = <method-wrapper '__ge__' of TypeError object>
    __getattribute__ = <method-wrapper '__getattribute__' of TypeError object>
    __gt__ = <method-wrapper '__gt__' of TypeError object>
    __hash__ = <method-wrapper '__hash__' of TypeError object>
    __init__ = <method-wrapper '__init__' of TypeError object>
    __init_subclass__ = <built-in method __init_subclass__ of type object>
    __le__ = <method-wrapper '__le__' of TypeError object>
    __lt__ = <method-wrapper '__lt__' of TypeError object>
    __ne__ = <method-wrapper '__ne__' of TypeError object>
    __new__ = <built-in method __new__ of type object>
    __reduce__ = <built-in method __reduce__ of TypeError object>
    __reduce_ex__ = <built-in method __reduce_ex__ of TypeError object>
    __repr__ = <method-wrapper '__repr__' of TypeError object>
    __setattr__ = <method-wrapper '__setattr__' of TypeError object>
    __setstate__ = <built-in method __setstate__ of TypeError object>
    __sizeof__ = <built-in method __sizeof__ of TypeError object>
    __str__ = <method-wrapper '__str__' of TypeError object>
    __subclasshook__ = <built-in method __subclasshook__ of type object>
    __suppress_context__ = False
    __traceback__ = <traceback object>
    args = ("'str' object is not callable",)
    with_traceback = <built-in method with_traceback of TypeError object>

The above is a description of an error in a Python program.  Here is
the original traceback:

Traceback (most recent call last):
  File "/contrail-test/tcutils/wrappers.py", line 82, in wrapper
    result = function(self, *args, **kwargs)
  File "/contrail-test/serial_scripts/k8s_auth/test_policy_combo.py", line 190, in test_only_pods_deployments_services_in_easy_ns
    stackrc_dict=stackrc_dict, inputs=self.inputs)
  File "/contrail-test/tcutils/kubernetes/auth/resource_util.py", line 99, in perform_operations
    stackrc_file=stackrc_file, inputs=inputs)
  File "/contrail-test/tcutils/kubernetes/auth/resource_util.py", line 72, in resource_with_expectation
    logger.error('Error while %s %s' (resource, verb))
TypeError: 'str' object is not callable



2021-02-18 07:26:35,068 - DEBUG - Skipping xmpp flap check
2021-02-18 07:26:35,069 - INFO - 
2021-02-18 07:26:35,069 - INFO - END TEST : test_only_pods_deployments_services_in_easy_ns : FAILED[0:00:04]
2021-02-18 07:26:35,069 - INFO - --------------------------------------------------------------------------------
2021-02-18 07:26:35,076 - INFO - ================================================================================
2021-02-18 07:26:35,076 - INFO - STARTING TEST    : test_only_service_in_zomsrc_ns
2021-02-18 07:26:35,077 - INFO - TEST DESCRIPTION : 
        Description: Test to validate only userC can create and delete service in zomsrc namespace
         Test steps:
                1. Create stackrc_dict for userC
                2. Create the resource expectation list
                3. Perform create and delete operations in default namespace and zomsrc namespace
         Pass criteria: userC must only be able to create and delete service in zomsrc namespace and nothing else
         Maintainer : nuthanc@juniper.net
        
2021-02-18 07:26:36,376 - DEBUG - Skipping xmpp flap check
2021-02-18 07:26:36,376 - INFO - Initial checks done. Running the testcase now
2021-02-18 07:26:36,376 - INFO - 
2021-02-18 07:26:36,377 - DEBUG - Container None not in host 192.168.7.18, copying to  host itself
2021-02-18 07:26:38,318 - ERROR - TypeError
Python 3.6.8: /usr/bin/python3
Thu Feb 18 07:26:37 2021

A problem occurred in a Python script.  Here is the sequence of
function calls leading up to the error, in the order they occurred.

 /contrail-test/tcutils/wrappers.py in wrapper(self=<serial_scripts.k8s_auth.test_policy_combo.TestP...nly_service_in_zomsrc_ns[auth] id=0x7f03a386c240>, *args=(), **kwargs={})
   80             log.info('Initial checks done. Running the testcase now')
   81             log.info('')
   82             result = function(self, *args, **kwargs)
   83             if self.inputs.upgrade:
   84                 pid = os.getpid()
result = None
function = <function TestPolicyCombo.test_only_service_in_zomsrc_ns>
self = <serial_scripts.k8s_auth.test_policy_combo.TestP...nly_service_in_zomsrc_ns[auth] id=0x7f03a386c240>
args = ()
kwargs = {}

 /contrail-test/serial_scripts/k8s_auth/test_policy_combo.py in test_only_service_in_zomsrc_ns(self=<serial_scripts.k8s_auth.test_policy_combo.TestP...nly_service_in_zomsrc_ns[auth] id=0x7f03a386c240>)
  155         ResourceUtil.perform_operations(
  156             stackrc_dict=stackrc_dict,
  157             resource_expectation=resource_expectation, inputs=self.inputs)
  158         ResourceUtil.perform_operations(
  159             stackrc_dict=stackrc_dict,
resource_expectation = {'daemonset': False, 'deployment': False, 'ingress': False, 'namespace': False, 'network_attachment_definition': False, 'network_policy': False, 'pod': False, 'service': True}
inputs undefined
self = <serial_scripts.k8s_auth.test_policy_combo.TestP...nly_service_in_zomsrc_ns[auth] id=0x7f03a386c240>
self.inputs = <common.contrail_test_init.ContrailTestInit object>

 /contrail-test/tcutils/kubernetes/auth/resource_util.py in perform_operations(stackrc_dict={'auth_url': 'http://192.168.7.14:5000/v3', 'domain_name': 'userC_domain', 'password': 'c0ntrail123', 'project_name': 'userC_project', 'user_name': 'userC'}, resource_expectation={'daemonset': False, 'deployment': False, 'ingress': False, 'namespace': False, 'network_attachment_definition': False, 'network_policy': False, 'pod': False, 'service': True}, namespace='default', inputs=<common.contrail_test_init.ContrailTestInit object>)
   97             resource_expectation=resource_expectation,
   98             namespace=namespace,
   99             stackrc_file=stackrc_file, inputs=inputs)
  100         ResourceUtil.resource_with_expectation(
  101             verb='delete',
stackrc_file = '/var/tmp/templates/stackrc.sh'
inputs = <common.contrail_test_init.ContrailTestInit object>

 /contrail-test/tcutils/kubernetes/auth/resource_util.py in resource_with_expectation(verb='create', resource_expectation={'daemonset': False, 'deployment': False, 'ingress': False, 'namespace': False, 'network_attachment_definition': False, 'network_policy': False, 'pod': False, 'service': True}, namespace='default', stackrc_file='/var/tmp/templates/stackrc.sh', inputs=<common.contrail_test_init.ContrailTestInit object>)
   70                     else:
   71                         logger.error(error)
   72                     logger.error('Error while %s %s' (resource, verb))
   73                     raise Exception(error)
   74 
global logger = <Logger auth (DEBUG)>
logger.error = <bound method Logger.error of <Logger auth (DEBUG)>>
resource = 'service'
verb = 'create'
TypeError: 'str' object is not callable
    __cause__ = None
    __class__ = <class 'TypeError'>
    __context__ = None
    __delattr__ = <method-wrapper '__delattr__' of TypeError object>
    __dict__ = {}
    __dir__ = <built-in method __dir__ of TypeError object>
    __doc__ = 'Inappropriate argument type.'
    __eq__ = <method-wrapper '__eq__' of TypeError object>
    __format__ = <built-in method __format__ of TypeError object>
    __ge__ = <method-wrapper '__ge__' of TypeError object>
    __getattribute__ = <method-wrapper '__getattribute__' of TypeError object>
    __gt__ = <method-wrapper '__gt__' of TypeError object>
    __hash__ = <method-wrapper '__hash__' of TypeError object>
    __init__ = <method-wrapper '__init__' of TypeError object>
    __init_subclass__ = <built-in method __init_subclass__ of type object>
    __le__ = <method-wrapper '__le__' of TypeError object>
    __lt__ = <method-wrapper '__lt__' of TypeError object>
    __ne__ = <method-wrapper '__ne__' of TypeError object>
    __new__ = <built-in method __new__ of type object>
    __reduce__ = <built-in method __reduce__ of TypeError object>
    __reduce_ex__ = <built-in method __reduce_ex__ of TypeError object>
    __repr__ = <method-wrapper '__repr__' of TypeError object>
    __setattr__ = <method-wrapper '__setattr__' of TypeError object>
    __setstate__ = <built-in method __setstate__ of TypeError object>
    __sizeof__ = <built-in method __sizeof__ of TypeError object>
    __str__ = <method-wrapper '__str__' of TypeError object>
    __subclasshook__ = <built-in method __subclasshook__ of type object>
    __suppress_context__ = False
    __traceback__ = <traceback object>
    args = ("'str' object is not callable",)
    with_traceback = <built-in method with_traceback of TypeError object>

The above is a description of an error in a Python program.  Here is
the original traceback:

Traceback (most recent call last):
  File "/contrail-test/tcutils/wrappers.py", line 82, in wrapper
    result = function(self, *args, **kwargs)
  File "/contrail-test/serial_scripts/k8s_auth/test_policy_combo.py", line 157, in test_only_service_in_zomsrc_ns
    resource_expectation=resource_expectation, inputs=self.inputs)
  File "/contrail-test/tcutils/kubernetes/auth/resource_util.py", line 99, in perform_operations
    stackrc_file=stackrc_file, inputs=inputs)
  File "/contrail-test/tcutils/kubernetes/auth/resource_util.py", line 72, in resource_with_expectation
    logger.error('Error while %s %s' (resource, verb))
TypeError: 'str' object is not callable



2021-02-18 07:26:38,318 - DEBUG - Skipping xmpp flap check
2021-02-18 07:26:38,319 - INFO - 
2021-02-18 07:26:38,319 - INFO - END TEST : test_only_service_in_zomsrc_ns : FAILED[0:00:03]
2021-02-18 07:26:38,319 - INFO - --------------------------------------------------------------------------------
