time: 2021-02-24 10:11:29.740655Z
tags: worker-0
test: scripts.k8s_scripts.test_ingress.TestIngressClusterIp.test_ingress_ip_assignment[ci_k8s_sanity,k8s_sanity]
time: 2021-02-24 10:13:09.452880Z
successful: scripts.k8s_scripts.test_ingress.TestIngressClusterIp.test_ingress_ip_assignment[ci_k8s_sanity,k8s_sanity] [ multipart
]
tags: -worker-0
time: 2021-02-24 10:11:32.005194Z
tags: worker-1
test: scripts.k8s_scripts.test_policy.TestNetworkPolicyServiceIngress.test_ingress_rule_on_pod_with_service[ci_k8s_sanity,k8s_sanity]
time: 2021-02-24 10:14:11.056321Z
failure: scripts.k8s_scripts.test_policy.TestNetworkPolicyServiceIngress.test_ingress_rule_on_pod_with_service[ci_k8s_sanity,k8s_sanity] [ multipart
Content-Type: text/x-traceback;charset=utf8,language=python
traceback
1028
Traceback (most recent call last):
  File "/contrail-test/tcutils/wrappers.py", line 179, in wrapper
    raise TestFailed("\n ".join(errmsg))
tcutils.cores.TestFailed: Test failed: AssertionError
Python 3.6.8: /usr/bin/python3
Wed Feb 24 10:14:09 2021

A problem occurred in a Python script.  Here is the sequence of
function calls leading up to the error, in the order they occurred.

 /contrail-test/tcutils/wrappers.py in wrapper(self=<scripts.k8s_scripts.test_policy.TestNetworkPoli...vice[ci_k8s_sanity,k8s_sanity] id=0x7fbdc2698be0>, *args=(), **kwargs={})
   80             log.info('Initial checks done. Running the testcase now')
   81             log.info('')
   82             result = function(self, *args, **kwargs)
   83             if self.inputs.upgrade:
   84                 pid = os.getpid()
result = None
function = <function TestNetworkPolicyServiceIngress.test_ingress_rule_on_pod_with_service>
self = <scripts.k8s_scripts.test_policy.TestNetworkPoli...vice[ci_k8s_sanity,k8s_sanity] id=0x7fbdc2698be0>
args = ()
kwargs = {}

 /contrail-test/scripts/k8s_scripts/test_policy.py in test_ingress_rule_on_pod_with_service(self=<scripts.k8s_scripts.test_policy.TestNetworkPoli...vice[ci_k8s_sanity,k8s_sanity] id=0x7fbdc2698be0>)
 3179         assert self.validate_nginx_lb([self.web1_pod_ns1,self.web2_pod_ns1],
 3180                                       service_ns1.cluster_ip,
 3181                                       test_pod=self.client1_pod_ns2, expectation=False)
 3182         assert self.client2_pod_ns1.ping_with_certainty(self.client1_pod_ns1.pod_ip)
 3183         assert self.client1_pod_ns1.ping_with_certainty(self.client2_pod_ns1.pod_ip)
test_pod undefined
self = <scripts.k8s_scripts.test_policy.TestNetworkPoli...vice[ci_k8s_sanity,k8s_sanity] id=0x7fbdc2698be0>
self.client1_pod_ns2 = <k8s.pod.PodFixture object>
expectation undefined
AssertionError: 
    __cause__ = None
    __class__ = <class 'AssertionError'>
    __context__ = None
    __delattr__ = <method-wrapper '__delattr__' of AssertionError object>
    __dict__ = {}
    __dir__ = <built-in method __dir__ of AssertionError object>
    __doc__ = 'Assertion failed.'
    __eq__ = <method-wrapper '__eq__' of AssertionError object>
    __format__ = <built-in method __format__ of AssertionError object>
    __ge__ = <method-wrapper '__ge__' of AssertionError object>
    __getattribute__ = <method-wrapper '__getattribute__' of AssertionError object>
    __gt__ = <method-wrapper '__gt__' of AssertionError object>
    __hash__ = <method-wrapper '__hash__' of AssertionError object>
    __init__ = <method-wrapper '__init__' of AssertionError object>
    __init_subclass__ = <built-in method __init_subclass__ of type object>
    __le__ = <method-wrapper '__le__' of AssertionError object>
    __lt__ = <method-wrapper '__lt__' of AssertionError object>
    __ne__ = <method-wrapper '__ne__' of AssertionError object>
    __new__ = <built-in method __new__ of type object>
    __reduce__ = <built-in method __reduce__ of AssertionError object>
    __reduce_ex__ = <built-in method __reduce_ex__ of AssertionError object>
    __repr__ = <method-wrapper '__repr__' of AssertionError object>
    __setattr__ = <method-wrapper '__setattr__' of AssertionError object>
    __setstate__ = <built-in method __setstate__ of AssertionError object>
    __sizeof__ = <built-in method __sizeof__ of AssertionError object>
    __str__ = <method-wrapper '__str__' of AssertionError object>
    __subclasshook__ = <built-in method __subclasshook__ of type object>
    __suppress_context__ = False
    __traceback__ = <traceback object>
    args = ()
    with_traceback = <built-in method with_traceback of AssertionError object>

The above is a description of an error in a Python program.  Here is
the original traceback:

Traceback (most recent call last):
  File "/contrail-test/tcutils/wrappers.py", line 82, in wrapper
    result = function(self, *args, **kwargs)
  File "/contrail-test/scripts/k8s_scripts/test_policy.py", line 3181, in test_ingress_rule_on_pod_with_service
    test_pod=self.client1_pod_ns2, expectation=False)
AssertionError



0
]
tags: -worker-1
