File: /var/log/contrail/kubernetes-kube-manager/contrail-kube-manager.log, Line: 25384
Error: exceptions.AttributeError, Timestamp: 2021-02-18 05:43:53
Details:
 02/18/2021 05:43:53.416 7ff87cd18eb0 [contrail-kube-manager] [ERROR]: <type 'exceptions.AttributeError'>
Python 2.7.5: /usr/bin/python
Thu Feb 18 05:43:53 2021

A problem occurred in a Python script.  Here is the sequence of
function calls leading up to the error, in the order they occurred.

 /usr/lib/python2.7/site-packages/cfgm_common/vnc_amqp.py in _vnc_subscribe_callback(self=<cfgm_common.vnc_amqp.VncAmqpHandle object>, oper_info={u'fq_name': [u'admin_domain'], u'obj_dict': {u'display_name': u'admin_domain', u'fq_name': [u'admin_domain'], u'id_perms': {u'created': u'2021-02-18T05:43:53.040231', u'creator': None, u'description': None, u'enable': True, u'last_modified': u'2021-02-18T05:43:53.040231', u'permissions': {u'group': u'cloud-admin-group', u'group_access': 7, u'other_access': 7, u'owner': u'cloud-admin', u'owner_access': 7}, u'user_visible': True, u'uuid': {u'uuid_lslong': 11967920078948680677L, u'uuid_mslong': 17472847525278139215L}}, u'perms2': {u'global_access': 0, u'owner': u'6d52ffceadf64a1bb907bb9dd95efc70', u'owner_access': 7, u'share': [{u'tenant': u'domain:f27c063f-c6c4-434f-a616-97e72e0043e5', u'tenant_access': 6}]}, u'uuid': u'f27c063f-c6c4-434f-a616-97e72e0043e5'}, u'oper': u'CREATE', u'request-id': u'req-32f6f7c5-ded7-49e7-92c7-c7d6621d5bea', u'type': u'domain', u'uuid': u'f27c063f-c6c4-434f-a616-97e72e0043e5'})
   85         try:
   86             self.oper_info = oper_info
   87             self.vnc_subscribe_actions()
   88 
   89         except ConnectionError:
self = <cfgm_common.vnc_amqp.VncAmqpHandle object>
self.vnc_subscribe_actions = <bound method VncAmqpHandle.vnc_subscribe_actions of <cfgm_common.vnc_amqp.VncAmqpHandle object>>

 /usr/lib/python2.7/site-packages/cfgm_common/vnc_amqp.py in vnc_subscribe_actions(self=<cfgm_common.vnc_amqp.VncAmqpHandle object>)
  149                     (self. obj_type, obj_id, oper))
  150             return
  151         self.evaluate_dependency()
  152 
  153     def _get_key_from_oper_info(self):
self = <cfgm_common.vnc_amqp.VncAmqpHandle object>
self.evaluate_dependency = <bound method VncAmqpHandle.evaluate_dependency of <cfgm_common.vnc_amqp.VncAmqpHandle object>>

 /usr/lib/python2.7/site-packages/cfgm_common/vnc_amqp.py in evaluate_dependency(self=<cfgm_common.vnc_amqp.VncAmqpHandle object>)
  254             return
  255 
  256         self.init_msgbus_fq_name()
  257         self.init_msgbus_dtr()
  258 
self = <cfgm_common.vnc_amqp.VncAmqpHandle object>
self.init_msgbus_fq_name = <bound method VncAmqpHandle.init_msgbus_fq_name of <cfgm_common.vnc_amqp.VncAmqpHandle object>>

 /usr/lib/python2.7/site-packages/cfgm_common/vnc_amqp.py in init_msgbus_fq_name(self=<cfgm_common.vnc_amqp.VncAmqpHandle object>)
  240 
  241     def init_msgbus_fq_name(self):
  242         self.msg_tracer.fq_name = self.obj.name
  243 
  244     def init_msgbus_dtr(self):
self = <cfgm_common.vnc_amqp.VncAmqpHandle object>
self.msg_tracer = MessageBusNotifyTrace(_context='', _scope='', _c...ne, _disable_sending_all_messages=False, _role=0)
self.msg_tracer.fq_name = None
self.obj = <kube_manager.vnc.config_db.DomainKM object>
self.obj.name undefined
<type 'exceptions.AttributeError'>: 'DomainKM' object has no attribute 'name'
    __class__ = <type 'exceptions.AttributeError'>
    __delattr__ = <method-wrapper '__delattr__' of exceptions.AttributeError object>
    __dict__ = {}
    __doc__ = 'Attribute not found.'
    __format__ = <built-in method __format__ of exceptions.AttributeError object>
    __getattribute__ = <method-wrapper '__getattribute__' of exceptions.AttributeError object>
    __getitem__ = <method-wrapper '__getitem__' of exceptions.AttributeError object>
    __getslice__ = <method-wrapper '__getslice__' of exceptions.AttributeError object>
    __hash__ = <method-wrapper '__hash__' of exceptions.AttributeError object>
    __init__ = <method-wrapper '__init__' of exceptions.AttributeError object>
    __new__ = <built-in method __new__ of type object>
    __reduce__ = <built-in method __reduce__ of exceptions.AttributeError object>
    __reduce_ex__ = <built-in method __reduce_ex__ of exceptions.AttributeError object>
    __repr__ = <method-wrapper '__repr__' of exceptions.AttributeError object>
    __setattr__ = <method-wrapper '__setattr__' of exceptions.AttributeError object>
    __setstate__ = <built-in method __setstate__ of exceptions.AttributeError object>
    __sizeof__ = <built-in method __sizeof__ of exceptions.AttributeError object>
    __str__ = <method-wrapper '__str__' of exceptions.AttributeError object>
    __subclasshook__ = <built-in method __subclasshook__ of type object>
    __unicode__ = <built-in method __unicode__ of exceptions.AttributeError object>
    args = ("'DomainKM' object has no attribute 'name'",)
    message = "'DomainKM' object has no attribute 'name'"

The above is a description of an error in a Python program.  Here is
the original traceback:

Traceback (most recent call last):
  File "/usr/lib/python2.7/site-packages/cfgm_common/vnc_amqp.py", line 87, in _vnc_subscribe_callback
    self.vnc_subscribe_actions()
  File "/usr/lib/python2.7/site-packages/cfgm_common/vnc_amqp.py", line 151, in vnc_subscribe_actions
    self.evaluate_dependency()
  File "/usr/lib/python2.7/site-packages/cfgm_common/vnc_amqp.py", line 256, in evaluate_dependency
    self.init_msgbus_fq_name()
  File "/usr/lib/python2.7/site-packages/cfgm_common/vnc_amqp.py", line 242, in init_msgbus_fq_name
    self.msg_tracer.fq_name = self.obj.name
AttributeError: 'DomainKM' object has no attribute 'name'
--------------------------------------------------------------------------------
File: /var/log/contrail/kubernetes-kube-manager/contrail-kube-manager.log, Line: 25469
Error: exceptions.AttributeError, Timestamp: 2021-02-18 05:43:53
Details:
 02/18/2021 05:43:53.416 7ff87cd18eb0 [contrail-kube-manager] [ERROR]: __default__ [SYS_ERR]: KubeManagerErrorLog: <type 'exceptions.AttributeError'>
Python 2.7.5: /usr/bin/python
Thu Feb 18 05:43:53 2021

A problem occurred in a Python script.  Here is the sequence of
function calls leading up to the error, in the order they occurred.

 /usr/lib/python2.7/site-packages/cfgm_common/vnc_amqp.py in _vnc_subscribe_callback(self=<cfgm_common.vnc_amqp.VncAmqpHandle object>, oper_info={u'fq_name': [u'admin_domain'], u'obj_dict': {u'display_name': u'admin_domain', u'fq_name': [u'admin_domain'], u'id_perms': {u'created': u'2021-02-18T05:43:53.040231', u'creator': None, u'description': None, u'enable': True, u'last_modified': u'2021-02-18T05:43:53.040231', u'permissions': {u'group': u'cloud-admin-group', u'group_access': 7, u'other_access': 7, u'owner': u'cloud-admin', u'owner_access': 7}, u'user_visible': True, u'uuid': {u'uuid_lslong': 11967920078948680677L, u'uuid_mslong': 17472847525278139215L}}, u'perms2': {u'global_access': 0, u'owner': u'6d52ffceadf64a1bb907bb9dd95efc70', u'owner_access': 7, u'share': [{u'tenant': u'domain:f27c063f-c6c4-434f-a616-97e72e0043e5', u'tenant_access': 6}]}, u'uuid': u'f27c063f-c6c4-434f-a616-97e72e0043e5'}, u'oper': u'CREATE', u'request-id': u'req-32f6f7c5-ded7-49e7-92c7-c7d6621d5bea', u'type': u'domain', u'uuid': u'f27c063f-c6c4-434f-a616-97e72e0043e5'})
   85         try:
   86             self.oper_info = oper_info
   87             self.vnc_subscribe_actions()
   88 
   89         except ConnectionError:
self = <cfgm_common.vnc_amqp.VncAmqpHandle object>
self.vnc_subscribe_actions = <bound method VncAmqpHandle.vnc_subscribe_actions of <cfgm_common.vnc_amqp.VncAmqpHandle object>>

 /usr/lib/python2.7/site-packages/cfgm_common/vnc_amqp.py in vnc_subscribe_actions(self=<cfgm_common.vnc_amqp.VncAmqpHandle object>)
  149                     (self. obj_type, obj_id, oper))
  150             return
  151         self.evaluate_dependency()
  152 
  153     def _get_key_from_oper_info(self):
self = <cfgm_common.vnc_amqp.VncAmqpHandle object>
self.evaluate_dependency = <bound method VncAmqpHandle.evaluate_dependency of <cfgm_common.vnc_amqp.VncAmqpHandle object>>

 /usr/lib/python2.7/site-packages/cfgm_common/vnc_amqp.py in evaluate_dependency(self=<cfgm_common.vnc_amqp.VncAmqpHandle object>)
  254             return
  255 
  256         self.init_msgbus_fq_name()
  257         self.init_msgbus_dtr()
  258 
self = <cfgm_common.vnc_amqp.VncAmqpHandle object>
self.init_msgbus_fq_name = <bound method VncAmqpHandle.init_msgbus_fq_name of <cfgm_common.vnc_amqp.VncAmqpHandle object>>

 /usr/lib/python2.7/site-packages/cfgm_common/vnc_amqp.py in init_msgbus_fq_name(self=<cfgm_common.vnc_amqp.VncAmqpHandle object>)
  240 
  241     def init_msgbus_fq_name(self):
  242         self.msg_tracer.fq_name = self.obj.name
  243 
  244     def init_msgbus_dtr(self):
self = <cfgm_common.vnc_amqp.VncAmqpHandle object>
self.msg_tracer = MessageBusNotifyTrace(_context='', _scope='', _c...ne, _disable_sending_all_messages=False, _role=0)
self.msg_tracer.fq_name = None
self.obj = <kube_manager.vnc.config_db.DomainKM object>
self.obj.name undefined
<type 'exceptions.AttributeError'>: 'DomainKM' object has no attribute 'name'
    __class__ = <type 'exceptions.AttributeError'>
    __delattr__ = <method-wrapper '__delattr__' of exceptions.AttributeError object>
    __dict__ = {}
    __doc__ = 'Attribute not found.'
    __format__ = <built-in method __format__ of exceptions.AttributeError object>
    __getattribute__ = <method-wrapper '__getattribute__' of exceptions.AttributeError object>
    __getitem__ = <method-wrapper '__getitem__' of exceptions.AttributeError object>
    __getslice__ = <method-wrapper '__getslice__' of exceptions.AttributeError object>
    __hash__ = <method-wrapper '__hash__' of exceptions.AttributeError object>
    __init__ = <method-wrapper '__init__' of exceptions.AttributeError object>
    __new__ = <built-in method __new__ of type object>
    __reduce__ = <built-in method __reduce__ of exceptions.AttributeError object>
    __reduce_ex__ = <built-in method __reduce_ex__ of exceptions.AttributeError object>
    __repr__ = <method-wrapper '__repr__' of exceptions.AttributeError object>
    __setattr__ = <method-wrapper '__setattr__' of exceptions.AttributeError object>
    __setstate__ = <built-in method __setstate__ of exceptions.AttributeError object>
    __sizeof__ = <built-in method __sizeof__ of exceptions.AttributeError object>
    __str__ = <method-wrapper '__str__' of exceptions.AttributeError object>
    __subclasshook__ = <built-in method __subclasshook__ of type object>
    __unicode__ = <built-in method __unicode__ of exceptions.AttributeError object>
    args = ("'DomainKM' object has no attribute 'name'",)
    message = "'DomainKM' object has no attribute 'name'"

The above is a description of an error in a Python program.  Here is
the original traceback:

Traceback (most recent call last):
  File "/usr/lib/python2.7/site-packages/cfgm_common/vnc_amqp.py", line 87, in _vnc_subscribe_callback
    self.vnc_subscribe_actions()
  File "/usr/lib/python2.7/site-packages/cfgm_common/vnc_amqp.py", line 151, in vnc_subscribe_actions
    self.evaluate_dependency()
  File "/usr/lib/python2.7/site-packages/cfgm_common/vnc_amqp.py", line 256, in evaluate_dependency
    self.init_msgbus_fq_name()
  File "/usr/lib/python2.7/site-packages/cfgm_common/vnc_amqp.py", line 242, in init_msgbus_fq_name
    self.msg_tracer.fq_name = self.obj.name
AttributeError: 'DomainKM' object has no attribute 'name'
--------------------------------------------------------------------------------
